Workbook

Sheet MoveData
A1: move_id | B1: 招式 | C1: 起手/蓄气 | D1: 维持 | E1: 击中 | F1: 卡肉 | G1: MV | H1: MV_ele | I1: 总帧数 | J1: 蓄力(Y/N)
A2: 1 | B2: 直斩 | C2: 18 | D2: 0 | E2: 15 | F2: 0 | G2: 30 | H2: 1 | I2: =SUM(C2,D2,E2,F2) -> 33 | J2: N
A3: 2 | B3: 蓄力斩 | C3: 71 | D3: 5 | E3: 27 | F3: 8 | G3: 110 | H3: 1.5 | I3: =SUM(C3,D3,E3,F3) -> 111 | J3: Y
A4: 3 | B4: 强蓄力斩 | C4: 71 | D4: 5 | E4: 33 | F4: 8 | G4: 131 | H4: 1.7 | I4: =SUM(C4,D4,E4,F4) -> 117 | J4: Y
A5: 4 | B5: 强横扫斩 | C5: 77 | D5: 0 | E5: 0 | F5: 20 | G5: 78 | H5: 1.5 | I5: =SUM(C5,D5,E5,F5) -> 97 | J5: N
A6: 5 | B6: 真蓄力斩（强击） | C6: 71 | D6: 5 | E6: 85 | F6: 35 | G6: 286 | H6: 2.8 | I6: =SUM(C6,D6,E6,F6) -> 196 | J6: Y
A7: 6 | B7: 强化射击 | C7: 26 | D7: 0 | E7: 0 | F7: 0 | G7: 0 | H7: 0 | I7: =SUM(C7,D7,E7,F7) -> 26 | J7: N
A8: 7 | B8: 回避 | C8: 21 | D8: 0 | E8: 0 | F8: 0 | G8: 0 | H8: 0 | I8: =SUM(C8,D8,E8,F8) -> 21 | J8: N
A9: 8 | B9: 纳刀 | C9: 22 | D9: 0 | E9: 0 | F9: 0 | G9: 0 | H9: 0 | I9: =SUM(C9,D9,E9,F9) -> 22 | J9: N

Sheet Combo
A1: combo_id | B1: combo_name | C1: move_1 | D1: move_2 | E1: move_3 | F1: move_4 | G1: move_5
A2: COMBO_DRAW_SLASH | B2: 蹭刀 | C2: 直斩 | D2: 回避 | E2: 纳刀
A3: COMBO_DRAW_CHARGE | B3: 拔刀三蓄 | C3: 蓄力斩 | D3: 回避 | E3: 纳刀
A4: COMBO_DRAW_STRONG | B4: 拔刀三蓄+强蓄 | C4: 蓄力斩 | D4: 强蓄力斩 | E4: 回避 | F4: 纳刀
A5: COMBO_DRAW_STRONG_SWEEP | B5: 拔刀三蓄+强蓄+强横 | C5: 蓄力斩 | D5: 强蓄力斩 | E5: 强横扫斩 | F5: 回避 | G5: 纳刀
A6: COMBO_FULL_CHARGE | B6: 完整蓄力连段 | C6: 蓄力斩 | D6: 强蓄力斩 | E6: 真蓄力斩（强击） | F6: 回避 | G6: 纳刀
A7: COMBO_SLINGER_TCS | B7: 直斩投射器真蓄 | C7: 直斩 | D7: 强化射击 | E7: 真蓄力斩（强击） | F7: 回避 | G7: 纳刀
A8: COMBO_CHARGE_SLINGER_TCS | B8: 三蓄投射器真蓄 | C8: 蓄力斩 | D8: 强化射击 | E8: 真蓄力斩（强击） | F8: 回避 | G8: 纳刀
A9: COMBO_ROLL_SLINGER_TCS | B9: 回避投射器真蓄 | C9: 回避 | D9: 强化射击 | E9: 真蓄力斩（强击） | F9: 回避 | G9: 纳刀

Sheet Combo_Calc
A1: combo_id | B1: combo_name | C1: MV_total | D1: MV_ele_total | E1: frames_base | F1: Mpf | G1: Epf | H1: charge_count | I1: charge_frame_per_charge | J1: sheathe_count
A2: COMBO_DRAW_SLASH | B2: =Combo!B2 -> 蹭刀 | C2: =SUM(_xlfn.XLOOKUP(Combo!C2,MoveData!B:B,MoveData!G:G),_xlfn.XLOOKUP(Combo!D2,MoveData!B:B,MoveData!G:G),_xlfn.XLOOKUP(Combo!E2,MoveData!B:B,MoveData!G:G),_xlfn.XLOOKUP(Combo!F2,MoveData!B:B,MoveData!G:G),_xlfn.XLOOKUP(Combo!G2,MoveData!B:B,MoveData!G:G)) -> 30 | D2: =SUM(_xlfn.XLOOKUP(Combo!C2,MoveData!B:B,MoveData!H:H),_xlfn.XLOOKUP(Combo!D2,MoveData!B:B,MoveData!H:H),_xlfn.XLOOKUP(Combo!E2,MoveData!B:B,MoveData!H:H),_xlfn.XLOOKUP(Combo!F2,MoveData!B:B,MoveData!H:H),_xlfn.XLOOKUP(Combo!G2,MoveData!B:B,MoveData!H:H)) -> 1 | E2: =SUM(_xlfn.XLOOKUP(Combo!C2,MoveData!B:B,MoveData!I:I),_xlfn.XLOOKUP(Combo!D2,MoveData!B:B,MoveData!I:I),_xlfn.XLOOKUP(Combo!E2,MoveData!B:B,MoveData!I:I),_xlfn.XLOOKUP(Combo!F2,MoveData!B:B,MoveData!I:I),_xlfn.XLOOKUP(Combo!G2,MoveData!B:B,MoveData!I:I)) -> 76 | F2: =C2/E2 -> 0.39473684 | G2: =D2/E2 -> 0.013157895 | H2: 0 | I2: 71 | J2: 1
A3: COMBO_DRAW_CHARGE | B3: =Combo!B3 -> 拔刀三蓄 | C3: =SUM(_xlfn.XLOOKUP(Combo!C3,MoveData!B:B,MoveData!G:G),_xlfn.XLOOKUP(Combo!D3,MoveData!B:B,MoveData!G:G),_xlfn.XLOOKUP(Combo!E3,MoveData!B:B,MoveData!G:G),_xlfn.XLOOKUP(Combo!F3,MoveData!B:B,MoveData!G:G),_xlfn.XLOOKUP(Combo!G3,MoveData!B:B,MoveData!G:G)) -> 110 | D3: =SUM(_xlfn.XLOOKUP(Combo!C3,MoveData!B:B,MoveData!H:H),_xlfn.XLOOKUP(Combo!D3,MoveData!B:B,MoveData!H:H),_xlfn.XLOOKUP(Combo!E3,MoveData!B:B,MoveData!H:H),_xlfn.XLOOKUP(Combo!F3,MoveData!B:B,MoveData!H:H),_xlfn.XLOOKUP(Combo!G3,MoveData!B:B,MoveData!H:H)) -> 1.5 | E3: =SUM(_xlfn.XLOOKUP(Combo!C3,MoveData!B:B,MoveData!I:I),_xlfn.XLOOKUP(Combo!D3,MoveData!B:B,MoveData!I:I),_xlfn.XLOOKUP(Combo!E3,MoveData!B:B,MoveData!I:I),_xlfn.XLOOKUP(Combo!F3,MoveData!B:B,MoveData!I:I),_xlfn.XLOOKUP(Combo!G3,MoveData!B:B,MoveData!I:I)) -> 154 | F3: =C3/E3 -> 0.71428571 | G3: =D3/E3 -> 0.0097402597 | H3: 1 | I3: 71 | J3: 1
A4: COMBO_DRAW_STRONG | B4: =Combo!B4 -> 拔刀三蓄+强蓄 | C4: =SUM(_xlfn.XLOOKUP(Combo!C4,MoveData!B:B,MoveData!G:G),_xlfn.XLOOKUP(Combo!D4,MoveData!B:B,MoveData!G:G),_xlfn.XLOOKUP(Combo!E4,MoveData!B:B,MoveData!G:G),_xlfn.XLOOKUP(Combo!F4,MoveData!B:B,MoveData!G:G),_xlfn.XLOOKUP(Combo!G4,MoveData!B:B,MoveData!G:G)) -> 241 | D4: =SUM(_xlfn.XLOOKUP(Combo!C4,MoveData!B:B,MoveData!H:H),_xlfn.XLOOKUP(Combo!D4,MoveData!B:B,MoveData!H:H),_xlfn.XLOOKUP(Combo!E4,MoveData!B:B,MoveData!H:H),_xlfn.XLOOKUP(Combo!F4,MoveData!B:B,MoveData!H:H),_xlfn.XLOOKUP(Combo!G4,MoveData!B:B,MoveData!H:H)) -> 3.2 | E4: =SUM(_xlfn.XLOOKUP(Combo!C4,MoveData!B:B,MoveData!I:I),_xlfn.XLOOKUP(Combo!D4,MoveData!B:B,MoveData!I:I),_xlfn.XLOOKUP(Combo!E4,MoveData!B:B,MoveData!I:I),_xlfn.XLOOKUP(Combo!F4,MoveData!B:B,MoveData!I:I),_xlfn.XLOOKUP(Combo!G4,MoveData!B:B,MoveData!I:I)) -> 271 | F4: =C4/E4 -> 0.88929889 | G4: =D4/E4 -> 0.011808118 | H4: 2 | I4: 71 | J4: 1
A5: COMBO_DRAW_STRONG_SWEEP | B5: =Combo!B5 -> 拔刀三蓄+强蓄+强横 | C5: =SUM(_xlfn.XLOOKUP(Combo!C5,MoveData!B:B,MoveData!G:G),_xlfn.XLOOKUP(Combo!D5,MoveData!B:B,MoveData!G:G),_xlfn.XLOOKUP(Combo!E5,MoveData!B:B,MoveData!G:G),_xlfn.XLOOKUP(Combo!F5,MoveData!B:B,MoveData!G:G),_xlfn.XLOOKUP(Combo!G5,MoveData!B:B,MoveData!G:G)) -> 319 | D5: =SUM(_xlfn.XLOOKUP(Combo!C5,MoveData!B:B,MoveData!H:H),_xlfn.XLOOKUP(Combo!D5,MoveData!B:B,MoveData!H:H),_xlfn.XLOOKUP(Combo!E5,MoveData!B:B,MoveData!H:H),_xlfn.XLOOKUP(Combo!F5,MoveData!B:B,MoveData!H:H),_xlfn.XLOOKUP(Combo!G5,MoveData!B:B,MoveData!H:H)) -> 4.7 | E5: =SUM(_xlfn.XLOOKUP(Combo!C5,MoveData!B:B,MoveData!I:I),_xlfn.XLOOKUP(Combo!D5,MoveData!B:B,MoveData!I:I),_xlfn.XLOOKUP(Combo!E5,MoveData!B:B,MoveData!I:I),_xlfn.XLOOKUP(Combo!F5,MoveData!B:B,MoveData!I:I),_xlfn.XLOOKUP(Combo!G5,MoveData!B:B,MoveData!I:I)) -> 368 | F5: =C5/E5 -> 0.86684783 | G5: =D5/E5 -> 0.012771739 | H5: 2 | I5: 71 | J5: 1
A6: COMBO_FULL_CHARGE | B6: =Combo!B6 -> 完整蓄力连段 | C6: =SUM(_xlfn.XLOOKUP(Combo!C6,MoveData!B:B,MoveData!G:G),_xlfn.XLOOKUP(Combo!D6,MoveData!B:B,MoveData!G:G),_xlfn.XLOOKUP(Combo!E6,MoveData!B:B,MoveData!G:G),_xlfn.XLOOKUP(Combo!F6,MoveData!B:B,MoveData!G:G),_xlfn.XLOOKUP(Combo!G6,MoveData!B:B,MoveData!G:G)) -> 527 | D6: =SUM(_xlfn.XLOOKUP(Combo!C6,MoveData!B:B,MoveData!H:H),_xlfn.XLOOKUP(Combo!D6,MoveData!B:B,MoveData!H:H),_xlfn.XLOOKUP(Combo!E6,MoveData!B:B,MoveData!H:H),_xlfn.XLOOKUP(Combo!F6,MoveData!B:B,MoveData!H:H),_xlfn.XLOOKUP(Combo!G6,MoveData!B:B,MoveData!H:H)) -> 6 | E6: =SUM(_xlfn.XLOOKUP(Combo!C6,MoveData!B:B,MoveData!I:I),_xlfn.XLOOKUP(Combo!D6,MoveData!B:B,MoveData!I:I),_xlfn.XLOOKUP(Combo!E6,MoveData!B:B,MoveData!I:I),_xlfn.XLOOKUP(Combo!F6,MoveData!B:B,MoveData!I:I),_xlfn.XLOOKUP(Combo!G6,MoveData!B:B,MoveData!I:I)) -> 467 | F6: =C6/E6 -> 1.1284797 | G6: =D6/E6 -> 0.012847966 | H6: 3 | I6: 71 | J6: 1
A7: COMBO_SLINGER_TCS | B7: =Combo!B7 -> 直斩投射器真蓄 | C7: =SUM(_xlfn.XLOOKUP(Combo!C7,MoveData!B:B,MoveData!G:G),_xlfn.XLOOKUP(Combo!D7,MoveData!B:B,MoveData!G:G),_xlfn.XLOOKUP(Combo!E7,MoveData!B:B,MoveData!G:G),_xlfn.XLOOKUP(Combo!F7,MoveData!B:B,MoveData!G:G),_xlfn.XLOOKUP(Combo!G7,MoveData!B:B,MoveData!G:G)) -> 316 | D7: =SUM(_xlfn.XLOOKUP(Combo!C7,MoveData!B:B,MoveData!H:H),_xlfn.XLOOKUP(Combo!D7,MoveData!B:B,MoveData!H:H),_xlfn.XLOOKUP(Combo!E7,MoveData!B:B,MoveData!H:H),_xlfn.XLOOKUP(Combo!F7,MoveData!B:B,MoveData!H:H),_xlfn.XLOOKUP(Combo!G7,MoveData!B:B,MoveData!H:H)) -> 3.8 | E7: =SUM(_xlfn.XLOOKUP(Combo!C7,MoveData!B:B,MoveData!I:I),_xlfn.XLOOKUP(Combo!D7,MoveData!B:B,MoveData!I:I),_xlfn.XLOOKUP(Combo!E7,MoveData!B:B,MoveData!I:I),_xlfn.XLOOKUP(Combo!F7,MoveData!B:B,MoveData!I:I),_xlfn.XLOOKUP(Combo!G7,MoveData!B:B,MoveData!I:I)) -> 298 | F7: =C7/E7 -> 1.0604027 | G7: =D7/E7 -> 0.012751678 | H7: 1 | I7: 71 | J7: 1
A8: COMBO_CHARGE_SLINGER_TCS | B8: =Combo!B8 -> 三蓄投射器真蓄 | C8: =SUM(_xlfn.XLOOKUP(Combo!C8,MoveData!B:B,MoveData!G:G),_xlfn.XLOOKUP(Combo!D8,MoveData!B:B,MoveData!G:G),_xlfn.XLOOKUP(Combo!E8,MoveData!B:B,MoveData!G:G),_xlfn.XLOOKUP(Combo!F8,MoveData!B:B,MoveData!G:G),_xlfn.XLOOKUP(Combo!G8,MoveData!B:B,MoveData!G:G)) -> 396 | D8: =SUM(_xlfn.XLOOKUP(Combo!C8,MoveData!B:B,MoveData!H:H),_xlfn.XLOOKUP(Combo!D8,MoveData!B:B,MoveData!H:H),_xlfn.XLOOKUP(Combo!E8,MoveData!B:B,MoveData!H:H),_xlfn.XLOOKUP(Combo!F8,MoveData!B:B,MoveData!H:H),_xlfn.XLOOKUP(Combo!G8,MoveData!B:B,MoveData!H:H)) -> 4.3 | E8: =SUM(_xlfn.XLOOKUP(Combo!C8,MoveData!B:B,MoveData!I:I),_xlfn.XLOOKUP(Combo!D8,MoveData!B:B,MoveData!I:I),_xlfn.XLOOKUP(Combo!E8,MoveData!B:B,MoveData!I:I),_xlfn.XLOOKUP(Combo!F8,MoveData!B:B,MoveData!I:I),_xlfn.XLOOKUP(Combo!G8,MoveData!B:B,MoveData!I:I)) -> 376 | F8: =C8/E8 -> 1.0531915 | G8: =D8/E8 -> 0.01143617 | H8: 2 | I8: 71 | J8: 1
A9: COMBO_ROLL_SLINGER_TCS | B9: =Combo!B9 -> 回避投射器真蓄 | C9: =SUM(_xlfn.XLOOKUP(Combo!C9,MoveData!B:B,MoveData!G:G),_xlfn.XLOOKUP(Combo!D9,MoveData!B:B,MoveData!G:G),_xlfn.XLOOKUP(Combo!E9,MoveData!B:B,MoveData!G:G),_xlfn.XLOOKUP(Combo!F9,MoveData!B:B,MoveData!G:G),_xlfn.XLOOKUP(Combo!G9,MoveData!B:B,MoveData!G:G)) -> 286 | D9: =SUM(_xlfn.XLOOKUP(Combo!C9,MoveData!B:B,MoveData!H:H),_xlfn.XLOOKUP(Combo!D9,MoveData!B:B,MoveData!H:H),_xlfn.XLOOKUP(Combo!E9,MoveData!B:B,MoveData!H:H),_xlfn.XLOOKUP(Combo!F9,MoveData!B:B,MoveData!H:H),_xlfn.XLOOKUP(Combo!G9,MoveData!B:B,MoveData!H:H)) -> 2.8 | E9: =SUM(_xlfn.XLOOKUP(Combo!C9,MoveData!B:B,MoveData!I:I),_xlfn.XLOOKUP(Combo!D9,MoveData!B:B,MoveData!I:I),_xlfn.XLOOKUP(Combo!E9,MoveData!B:B,MoveData!I:I),_xlfn.XLOOKUP(Combo!F9,MoveData!B:B,MoveData!I:I),_xlfn.XLOOKUP(Combo!G9,MoveData!B:B,MoveData!I:I)) -> 286 | F9: =C9/E9 -> 1 | G9: =D9/E9 -> 0.0097902098 | H9: 1 | I9: 71 | J9: 1

Sheet Skills
A1: key | B1: skill | C1: level | D1: level_max | E1: coverage_key | F1: include_in_recommend | G1: ATK_plus | H1: ATK_multi | I1: CRT_plus | J1: CD | K1: WEX_raw_CRT | L1: WEX_soft_CRT | M1: focus_reduce_pct | N1: sheathe_reduce_frames | O1: ELE_plus | P1: ELE_multi | Q1: status_plus | R1: status_multi | S1: action_multi | T1: sharpness_effect | U1: condition_note
A2: =B2&"|"&C2 -> 攻击|0 | B2: 攻击 | C2: 0 | D2: 7 | E2: always | F2: TRUE | G2: 0 | H2: 1 | I2: 0 | J2: 1.25 | K2: 0 | L2: 0 | M2: 0 | N2: 0 | O2: 0 | P2: 1 | Q2: 0 | R2: 1 | S2: 1 | T2: 0
A3: =B3&"|"&C3 -> 攻击|1 | B3: 攻击 | C3: 1 | D3: 7 | E3: always | F3: TRUE | G3: 3 | H3: 1 | I3: 0 | J3: 1.25 | K3: 0 | L3: 0 | M3: 0 | N3: 0 | O3: 0 | P3: 1 | Q3: 0 | R3: 1 | S3: 1 | T3: 0 | U3: 无条件
A4: =B4&"|"&C4 -> 攻击|2 | B4: 攻击 | C4: 2 | D4: 7 | E4: always | F4: TRUE | G4: 6 | H4: 1 | I4: 0 | J4: 1.25 | K4: 0 | L4: 0 | M4: 0 | N4: 0 | O4: 0 | P4: 1 | Q4: 0 | R4: 1 | S4: 1 | T4: 0 | U4: 无条件
A5: =B5&"|"&C5 -> 攻击|3 | B5: 攻击 | C5: 3 | D5: 7 | E5: always | F5: TRUE | G5: 9 | H5: 1 | I5: 0 | J5: 1.25 | K5: 0 | L5: 0 | M5: 0 | N5: 0 | O5: 0 | P5: 1 | Q5: 0 | R5: 1 | S5: 1 | T5: 0 | U5: 无条件
A6: =B6&"|"&C6 -> 攻击|4 | B6: 攻击 | C6: 4 | D6: 7 | E6: always | F6: TRUE | G6: 12 | H6: 1 | I6: 0.05 | J6: 1.25 | K6: 0 | L6: 0 | M6: 0 | N6: 0 | O6: 0 | P6: 1 | Q6: 0 | R6: 1 | S6: 1 | T6: 0 | U6: L4 起附带会心
A7: =B7&"|"&C7 -> 攻击|5 | B7: 攻击 | C7: 5 | D7: 7 | E7: always | F7: TRUE | G7: 15 | H7: 1 | I7: 0.05 | J7: 1.25 | K7: 0 | L7: 0 | M7: 0 | N7: 0 | O7: 0 | P7: 1 | Q7: 0 | R7: 1 | S7: 1 | T7: 0 | U7: 同上
A8: =B8&"|"&C8 -> 攻击|6 | B8: 攻击 | C8: 6 | D8: 7 | E8: always | F8: TRUE | G8: 18 | H8: 1 | I8: 0.05 | J8: 1.25 | K8: 0 | L8: 0 | M8: 0 | N8: 0 | O8: 0 | P8: 1 | Q8: 0 | R8: 1 | S8: 1 | T8: 0 | U8: 同上
A9: =B9&"|"&C9 -> 攻击|7 | B9: 攻击 | C9: 7 | D9: 7 | E9: always | F9: TRUE | G9: 21 | H9: 1 | I9: 0.05 | J9: 1.25 | K9: 0 | L9: 0 | M9: 0 | N9: 0 | O9: 0 | P9: 1 | Q9: 0 | R9: 1 | S9: 1 | T9: 0 | U9: 同上
A10: =B10&"|"&C10 -> 看破|0 | B10: 看破 | C10: 0 | D10: 7 | E10: always | F10: TRUE | G10: 0 | H10: 1 | I10: 0 | J10: 1.25 | K10: 0 | L10: 0 | M10: 0 | N10: 0 | O10: 0 | P10: 1 | Q10: 0 | R10: 1 | S10: 1 | T10: 0
A11: =B11&"|"&C11 -> 看破|1 | B11: 看破 | C11: 1 | D11: 7 | E11: always | F11: TRUE | G11: 0 | H11: 1 | I11: 0.05 | J11: 1.25 | K11: 0 | L11: 0 | M11: 0 | N11: 0 | O11: 0 | P11: 1 | Q11: 0 | R11: 1 | S11: 1 | T11: 0 | U11: 无条件
A12: =B12&"|"&C12 -> 看破|2 | B12: 看破 | C12: 2 | D12: 7 | E12: always | F12: TRUE | G12: 0 | H12: 1 | I12: 0.1 | J12: 1.25 | K12: 0 | L12: 0 | M12: 0 | N12: 0 | O12: 0 | P12: 1 | Q12: 0 | R12: 1 | S12: 1 | T12: 0 | U12: 无条件
A13: =B13&"|"&C13 -> 看破|3 | B13: 看破 | C13: 3 | D13: 7 | E13: always | F13: TRUE | G13: 0 | H13: 1 | I13: 0.15 | J13: 1.25 | K13: 0 | L13: 0 | M13: 0 | N13: 0 | O13: 0 | P13: 1 | Q13: 0 | R13: 1 | S13: 1 | T13: 0 | U13: 无条件
A14: =B14&"|"&C14 -> 看破|4 | B14: 看破 | C14: 4 | D14: 7 | E14: always | F14: TRUE | G14: 0 | H14: 1 | I14: 0.2 | J14: 1.25 | K14: 0 | L14: 0 | M14: 0 | N14: 0 | O14: 0 | P14: 1 | Q14: 0 | R14: 1 | S14: 1 | T14: 0 | U14: 无条件
A15: =B15&"|"&C15 -> 看破|5 | B15: 看破 | C15: 5 | D15: 7 | E15: always | F15: TRUE | G15: 0 | H15: 1 | I15: 0.25 | J15: 1.25 | K15: 0 | L15: 0 | M15: 0 | N15: 0 | O15: 0 | P15: 1 | Q15: 0 | R15: 1 | S15: 1 | T15: 0 | U15: 无条件
A16: =B16&"|"&C16 -> 看破|6 | B16: 看破 | C16: 6 | D16: 7 | E16: always | F16: TRUE | G16: 0 | H16: 1 | I16: 0.3 | J16: 1.25 | K16: 0 | L16: 0 | M16: 0 | N16: 0 | O16: 0 | P16: 1 | Q16: 0 | R16: 1 | S16: 1 | T16: 0 | U16: 无条件
A17: =B17&"|"&C17 -> 看破|7 | B17: 看破 | C17: 7 | D17: 7 | E17: always | F17: TRUE | G17: 0 | H17: 1 | I17: 0.4 | J17: 1.25 | K17: 0 | L17: 0 | M17: 0 | N17: 0 | O17: 0 | P17: 1 | Q17: 0 | R17: 1 | S17: 1 | T17: 0 | U17: 无条件
A18: =B18&"|"&C18 -> 超会心|0 | B18: 超会心 | C18: 0 | D18: 3 | E18: always | F18: TRUE | G18: 0 | H18: 1 | I18: 0 | J18: 1.25 | K18: 0 | L18: 0 | M18: 0 | N18: 0 | O18: 0 | P18: 1 | Q18: 0 | R18: 1 | S18: 1 | T18: 0
A19: =B19&"|"&C19 -> 超会心|1 | B19: 超会心 | C19: 1 | D19: 3 | E19: always | F19: TRUE | G19: 0 | H19: 1 | I19: 0 | J19: 1.3 | K19: 0 | L19: 0 | M19: 0 | N19: 0 | O19: 0 | P19: 1 | Q19: 0 | R19: 1 | S19: 1 | T19: 0 | U19: 会心时物理伤害倍率；基线 CD=1.25
A20: =B20&"|"&C20 -> 超会心|2 | B20: 超会心 | C20: 2 | D20: 3 | E20: always | F20: TRUE | G20: 0 | H20: 1 | I20: 0 | J20: 1.35 | K20: 0 | L20: 0 | M20: 0 | N20: 0 | O20: 0 | P20: 1 | Q20: 0 | R20: 1 | S20: 1 | T20: 0 | U20: 同上
A21: =B21&"|"&C21 -> 超会心|3 | B21: 超会心 | C21: 3 | D21: 3 | E21: always | F21: TRUE | G21: 0 | H21: 1 | I21: 0 | J21: 1.4 | K21: 0 | L21: 0 | M21: 0 | N21: 0 | O21: 0 | P21: 1 | Q21: 0 | R21: 1 | S21: 1 | T21: 0 | U21: 同上
A22: =B22&"|"&C22 -> 弱点特效|0 | B22: 弱点特效 | C22: 0 | D22: 3 | E22: wex | F22: TRUE | G22: 0 | H22: 1 | I22: 0 | J22: 1.25 | K22: 0 | L22: 0 | M22: 0 | N22: 0 | O22: 0 | P22: 1 | Q22: 0 | R22: 1 | S22: 1 | T22: 0
A23: =B23&"|"&C23 -> 弱点特效|1 | B23: 弱点特效 | C23: 1 | D23: 3 | E23: wex | F23: TRUE | G23: 0 | H23: 1 | I23: 0 | J23: 1.25 | K23: 0.1 | L23: 0.15 | M23: 0 | N23: 0 | O23: 0 | P23: 1 | Q23: 0 | R23: 1 | S23: 1 | T23: 0 | U23: 有效部位 +10%；受伤再 +5%
A24: =B24&"|"&C24 -> 弱点特效|2 | B24: 弱点特效 | C24: 2 | D24: 3 | E24: wex | F24: TRUE | G24: 0 | H24: 1 | I24: 0 | J24: 1.25 | K24: 0.15 | L24: 0.3 | M24: 0 | N24: 0 | O24: 0 | P24: 1 | Q24: 0 | R24: 1 | S24: 1 | T24: 0 | U24: 有效部位 +15%；受伤再 +15%
A25: =B25&"|"&C25 -> 弱点特效|3 | B25: 弱点特效 | C25: 3 | D25: 3 | E25: wex | F25: TRUE | G25: 0 | H25: 1 | I25: 0 | J25: 1.25 | K25: 0.3 | L25: 0.5 | M25: 0 | N25: 0 | O25: 0 | P25: 1 | Q25: 0 | R25: 1 | S25: 1 | T25: 0 | U25: 有效部位 +30%；受伤再 +20%
A26: =B26&"|"&C26 -> 挑战者|0 | B26: 挑战者 | C26: 0 | D26: 7 | E26: agitator | F26: TRUE | G26: 0 | H26: 1 | I26: 0 | J26: 1.25 | K26: 0 | L26: 0 | M26: 0 | N26: 0 | O26: 0 | P26: 1 | Q26: 0 | R26: 1 | S26: 1 | T26: 0
A27: =B27&"|"&C27 -> 挑战者|1 | B27: 挑战者 | C27: 1 | D27: 7 | E27: agitator | F27: TRUE | G27: 4 | H27: 1 | I27: 0.05 | J27: 1.25 | K27: 0 | L27: 0 | M27: 0 | N27: 0 | O27: 0 | P27: 1 | Q27: 0 | R27: 1 | S27: 1 | T27: 0 | U27: 怪物愤怒时
A28: =B28&"|"&C28 -> 挑战者|2 | B28: 挑战者 | C28: 2 | D28: 7 | E28: agitator | F28: TRUE | G28: 8 | H28: 1 | I28: 0.05 | J28: 1.25 | K28: 0 | L28: 0 | M28: 0 | N28: 0 | O28: 0 | P28: 1 | Q28: 0 | R28: 1 | S28: 1 | T28: 0 | U28: 怪物愤怒时
A29: =B29&"|"&C29 -> 挑战者|3 | B29: 挑战者 | C29: 3 | D29: 7 | E29: agitator | F29: TRUE | G29: 12 | H29: 1 | I29: 0.07 | J29: 1.25 | K29: 0 | L29: 0 | M29: 0 | N29: 0 | O29: 0 | P29: 1 | Q29: 0 | R29: 1 | S29: 1 | T29: 0 | U29: 怪物愤怒时
A30: =B30&"|"&C30 -> 挑战者|4 | B30: 挑战者 | C30: 4 | D30: 7 | E30: agitator | F30: TRUE | G30: 16 | H30: 1 | I30: 0.07 | J30: 1.25 | K30: 0 | L30: 0 | M30: 0 | N30: 0 | O30: 0 | P30: 1 | Q30: 0 | R30: 1 | S30: 1 | T30: 0 | U30: 怪物愤怒时
A31: =B31&"|"&C31 -> 挑战者|5 | B31: 挑战者 | C31: 5 | D31: 7 | E31: agitator | F31: TRUE | G31: 20 | H31: 1 | I31: 0.1 | J31: 1.25 | K31: 0 | L31: 0 | M31: 0 | N31: 0 | O31: 0 | P31: 1 | Q31: 0 | R31: 1 | S31: 1 | T31: 0 | U31: 怪物愤怒时
A32: =B32&"|"&C32 -> 挑战者|6 | B32: 挑战者 | C32: 6 | D32: 7 | E32: agitator | F32: TRUE | G32: 24 | H32: 1 | I32: 0.15 | J32: 1.25 | K32: 0 | L32: 0 | M32: 0 | N32: 0 | O32: 0 | P32: 1 | Q32: 0 | R32: 1 | S32: 1 | T32: 0 | U32: 怪物愤怒时
A33: =B33&"|"&C33 -> 挑战者|7 | B33: 挑战者 | C33: 7 | D33: 7 | E33: agitator | F33: TRUE | G33: 28 | H33: 1 | I33: 0.2 | J33: 1.25 | K33: 0 | L33: 0 | M33: 0 | N33: 0 | O33: 0 | P33: 1 | Q33: 0 | R33: 1 | S33: 1 | T33: 0 | U33: 怪物愤怒时
A34: =B34&"|"&C34 -> 无伤|0 | B34: 无伤 | C34: 0 | D34: 3 | E34: peak | F34: TRUE | G34: 0 | H34: 1 | I34: 0 | J34: 1.25 | K34: 0 | L34: 0 | M34: 0 | N34: 0 | O34: 0 | P34: 1 | Q34: 0 | R34: 1 | S34: 1 | T34: 0
A35: =B35&"|"&C35 -> 无伤|1 | B35: 无伤 | C35: 1 | D35: 3 | E35: peak | F35: TRUE | G35: 5 | H35: 1 | I35: 0 | J35: 1.25 | K35: 0 | L35: 0 | M35: 0 | N35: 0 | O35: 0 | P35: 1 | Q35: 0 | R35: 1 | S35: 1 | T35: 0 | U35: 满血时
A36: =B36&"|"&C36 -> 无伤|2 | B36: 无伤 | C36: 2 | D36: 3 | E36: peak | F36: TRUE | G36: 10 | H36: 1 | I36: 0 | J36: 1.25 | K36: 0 | L36: 0 | M36: 0 | N36: 0 | O36: 0 | P36: 1 | Q36: 0 | R36: 1 | S36: 1 | T36: 0 | U36: 满血时
A37: =B37&"|"&C37 -> 无伤|3 | B37: 无伤 | C37: 3 | D37: 3 | E37: peak | F37: TRUE | G37: 20 | H37: 1 | I37: 0 | J37: 1.25 | K37: 0 | L37: 0 | M37: 0 | N37: 0 | O37: 0 | P37: 1 | Q37: 0 | R37: 1 | S37: 1 | T37: 0 | U37: 满血时
A38: =B38&"|"&C38 -> 怨恨|0 | B38: 怨恨 | C38: 0 | D38: 5 | E38: resentment | F38: TRUE | G38: 0 | H38: 1 | I38: 0 | J38: 1.25 | K38: 0 | L38: 0 | M38: 0 | N38: 0 | O38: 0 | P38: 1 | Q38: 0 | R38: 1 | S38: 1 | T38: 0 | U38: 有红血槽时
A39: =B39&"|"&C39 -> 怨恨|1 | B39: 怨恨 | C39: 1 | D39: 5 | E39: resentment | F39: TRUE | G39: 5 | H39: 1 | I39: 0 | J39: 1.25 | K39: 0 | L39: 0 | M39: 0 | N39: 0 | O39: 0 | P39: 1 | Q39: 0 | R39: 1 | S39: 1 | T39: 0 | U39: 有红血槽时
A40: =B40&"|"&C40 -> 怨恨|2 | B40: 怨恨 | C40: 2 | D40: 5 | E40: resentment | F40: TRUE | G40: 10 | H40: 1 | I40: 0 | J40: 1.25 | K40: 0 | L40: 0 | M40: 0 | N40: 0 | O40: 0 | P40: 1 | Q40: 0 | R40: 1 | S40: 1 | T40: 0 | U40: 有红血槽时
...

Sheet Weapons
A1: weapon_id | B1: weapon_name | C1: weapon_type | D1: weapon_coef | E1: W_base | F1: Display_ATK | G1: weapon_crt | H1: ele_type | I1: weapon_ele | J1: sharpness | K1: S_phy | L1: S_ele | M1: 备注
A2: GS_001 | B2: 灭鬼凶器【断】 | C2: 大剑 | D2: 4.8 | E2: 280 | F2: =D2*E2 -> 1344 | G2: 0% | H2: 龙 | I2: 240 | J2: 白 | K2: 1.32 | L2: 1.15 | M2: 长白斩大剑
A3: GS_002 | B3: 煌黑大剑龙击 | C3: 大剑 | D3: 4.8 | E3: 280 | F3: =D3*E3 -> 1344 | G3: 0% | H3: 龙 | I3: 810 | J3: 紫 | K3: 1.39 | L3: 1.25 | M3: 高龙属性大剑
A4: GS_P1 | B4: 防卫队炎刃5 | C4: 大剑 | D4: 4.8 | E4: 220 | F4: =D4*E4 -> 1056 | G4: 0% | H4: 无 | I4: 0 | J4: 白 | K4: 1.32 | L4: 1.15 | M4: P1 新手档武器
A5: GS_P2 | B5: 黑龙玄刃 | C5: 大剑 | D5: 4.8 | E5: 340 | F5: =D5*E5 -> 1632 | G5: -30% | H5: 龙 | I5: 180 | J5: 紫 | K5: 1.39 | L5: 1.25 | M5: P2/P3 主模型武器
A6: DB_001 | B6: 残灭之爪【鬼】 | C6: 双刀 | D6: 1.4 | E6: 290 | F6: =D6*E6 -> 406 | G6: 0% | H6: 龙 | I6: 180 | J6: 白 | K6: 1.32 | L6: 1.15 | M6: 长白斩双刀，偏物理
A7: DB_002 | B7: 煌黑双剑烈狂 | C7: 双刀 | D7: 1.4 | E7: 280 | F7: =D7*E7 -> 392 | G7: 0% | H7: 龙 | I7: 480 | J7: 紫 | K7: 1.39 | L7: 1.25 | M7: 属性流双刀

Sheet Hitzone
A1: hitzone_id | B1: target | C1: state | D1: part | E1: H_cut | F1: H_dragon | G1: H_soft_cut | H1: weak_raw | I1: weak_soft | J1: Δ_soft% | K1: 备注
A2: TRAINING_POLE | B2: 训练场木桩 | C2: 固定 | D2: 木桩 | E2: 80 | F2: 30 | G2: =ROUNDDOWN(E2*0.75+25,0) -> 85 | H2: =IF(E2>=45,"Y","N") -> Y | I2: =IF(G2>=45,"Y","N") -> Y | J2: =G2/E2-1 -> 0.0625 | K2: 公式校验 / 4 武器对比
A3: RATH_HEAD | B3: 火龙 | C3: 通常 | D3: 头 | E3: 65 | F3: 30 | G3: =ROUNDDOWN(E3*0.75+25,0) -> 73 | H3: =IF(E3>=45,"Y","N") -> Y | I3: =IF(G3>=45,"Y","N") -> Y | J3: =G3/E3-1 -> 0.12307692 | K3: 最优输出点
A4: RATH_HEAD_RAGE | B4: 火龙 | C4: 愤怒 | D4: 头 | E4: 60 | F4: 30 | G4: =ROUNDDOWN(E4*0.75+25,0) -> 70 | H4: =IF(E4>=45,"Y","N") -> Y | I4: =IF(G4>=45,"Y","N") -> Y | J4: =G4/E4-1 -> 0.16666667 | K4: 怒后头部切断略降
A5: RATH_NECK | B5: 火龙 | C5: 通常 | D5: 颈 | E5: 35 | F5: 20 | G5: =ROUNDDOWN(E5*0.75+25,0) -> 51 | H5: =IF(E5>=45,"Y","N") -> N | I5: =IF(G5>=45,"Y","N") -> Y | J5: =G5/E5-1 -> 0.45714286 | K5: 软化后进入弱特区间
A6: RATH_NECK_RAGE | B6: 火龙 | C6: 愤怒 | D6: 颈 | E6: 35 | F6: 20 | G6: =ROUNDDOWN(E6*0.75+25,0) -> 51 | H6: =IF(E6>=45,"Y","N") -> N | I6: =IF(G6>=45,"Y","N") -> Y | J6: =G6/E6-1 -> 0.45714286 | K6: 怒后颈部打击略降
A7: RATH_BODY | B7: 火龙 | C7: 通常 | D7: 胴 | E7: 25 | F7: 20 | G7: =ROUNDDOWN(E7*0.75+25,0) -> 43 | H7: =IF(E7>=45,"Y","N") -> N | I7: =IF(G7>=45,"Y","N") -> N | J7: =G7/E7-1 -> 0.72 | K7: 软化后仍低于 45
A8: RATH_WING | B8: 火龙 | C8: 通常 | D8: 翼 | E8: 50 | F8: 25 | G8: =ROUNDDOWN(E8*0.75+25,0) -> 62 | H8: =IF(E8>=45,"Y","N") -> Y | I8: =IF(G8>=45,"Y","N") -> Y | J8: =G8/E8-1 -> 0.24 | K8: 弱特稳定触发
A9: RATH_WING_RAGE | B9: 火龙 | C9: 愤怒 | D9: 翼 | E9: 20 | F9: 25 | G9: =ROUNDDOWN(E9*0.75+25,0) -> 40 | H9: =IF(E9>=45,"Y","N") -> N | I9: =IF(G9>=45,"Y","N") -> N | J9: =G9/E9-1 -> 1 | K9: 翼部怒后弱特不触发
A10: RATH_LEG | B10: 火龙 | C10: 通常 | D10: 脚 | E10: 35 | F10: 15 | G10: =ROUNDDOWN(E10*0.75+25,0) -> 51 | H10: =IF(E10>=45,"Y","N") -> N | I10: =IF(G10>=45,"Y","N") -> Y | J10: =G10/E10-1 -> 0.45714286 | K10: 软化后进入弱特区间
A11: RATH_TAIL | B11: 火龙 | C11: 通常 | D11: 尾 | E11: 45 | F11: 20 | G11: =ROUNDDOWN(E11*0.75+25,0) -> 58 | H11: =IF(E11>=45,"Y","N") -> Y | I11: =IF(G11>=45,"Y","N") -> Y | J11: =G11/E11-1 -> 0.28888889 | K11: 临界弱特部位

Sheet Input
A1: 基础区
A2: weapon_id | B2: GS_P2
A3: combo_id | B3: COMBO_SLINGER_TCS
A4: hitzone_id | B4: TRAINING_POLE
A5: 是否软化 | B5: FALSE
A6: 刃中补正 | B6: 1.03
A8: Input 覆盖率区
A9: 弱特覆盖率 | B9: =C9/100 -> 0.6 | C9: 60
A10: 挑战者覆盖率 | B10: =C10/100 -> 0.75 | C10: 75
A11: 无伤覆盖率 | B11: =C11/100 -> 0.5 | C11: 50
A12: 怨恨覆盖率 | B12: =C12/100 -> 0.05 | C12: 5
A13: 力量解放覆盖率 | B13: =C13/100 -> 0.1 | C13: 10
A14: 精神抖擞覆盖率 | B14: =C14/100 -> 0.7 | C14: 70
A15: 火场怪力覆盖率 | B15: =C15/100 -> 0 | C15: 0
A16: 攻击守势覆盖率 | B16: =C16/100 -> 0 | C16: 0
A17: 转祸为福覆盖率 | B17: =C17/100 -> 0 | C17: 0
A19: Input Buff 区 | E19: Input 技能区
A20: 攻大猫饭 | B20: TRUE | E20: 攻击 | F20: 2
A21: 力量护符 | B21: TRUE | E21: 看破 | F21: 2
A22: 力量之爪 | B22: TRUE | E22: 弱点特效 | F22: 1
A23: 鬼人药 | B23: FALSE | E23: 超会心 | F23: 1
A24: 鬼人药G | B24: TRUE | E24: 挑战者 | F24: 3
A25: 怪力种子 | B25: TRUE | E25: 无伤 | F25: 1
A26: 鬼人粉尘 | B26: TRUE | E26: 怨恨 | F26: 0
A27: 短期催眠术 | B27: TRUE | E27: 集中 | F27: 0
E28: 属性强化 | F28: 0
E29: 力量解放 | F29: 0
E30: 精神抖擞 | F30: 0
E31: 纳刀术 | F31: 0

Sheet Calc_Current
A1: 武器数据 | B1: 当前值
A2: W_base | B2: =_xlfn.XLOOKUP(Input!$B$2,Weapons!$A:$A,Weapons!$E:$E) -> 340
A3: weapon_crt | B3: =_xlfn.XLOOKUP(Input!$B$2,Weapons!$A:$A,Weapons!$G:$G) -> -30%
A4: weapon_ele | B4: =_xlfn.XLOOKUP(Input!$B$2,Weapons!$A:$A,Weapons!$I:$I) -> 180
A5: S_phy | B5: =_xlfn.XLOOKUP(Input!$B$2,Weapons!$A:$A,Weapons!$K:$K) -> 1.39
A6: S_ele | B6: =_xlfn.XLOOKUP(Input!$B$2,Weapons!$A:$A,Weapons!$L:$L) -> 1.25
A8: 连段数据
A9: MV_total | B9: =_xlfn.XLOOKUP(Input!$B$3,Combo_Calc!$A:$A,Combo_Calc!$C:$C) -> 316
A10: MV_ele_total | B10: =_xlfn.XLOOKUP(Input!$B$3,Combo_Calc!$A:$A,Combo_Calc!$D:$D) -> 3.8
A11: frames_base | B11: =_xlfn.XLOOKUP(Input!$B$3,Combo_Calc!$A:$A,Combo_Calc!$E:$E) -> 298
A12: charge_count | B12: =_xlfn.XLOOKUP(Input!$B$3,Combo_Calc!$A:$A,Combo_Calc!$H:$H) -> 1
A13: charge_frame_per_charge | B13: =_xlfn.XLOOKUP(Input!$B$3,Combo_Calc!$A:$A,Combo_Calc!$I:$I) -> 71
A14: sheathe_count | B14: =_xlfn.XLOOKUP(Input!$B$3,Combo_Calc!$A:$A,Combo_Calc!$J:$J) -> 1
A16: 肉质数据
A17: H_cut | B17: =_xlfn.XLOOKUP(Input!$B$4,Hitzone!$A:$A,Hitzone!$E:$E) -> 80
A18: H_dragon | B18: =_xlfn.XLOOKUP(Input!$B$4,Hitzone!$A:$A,Hitzone!$F:$F) -> 30
A19: H_soft_cut | B19: =_xlfn.XLOOKUP(Input!$B$4,Hitzone!$A:$A,Hitzone!$G:$G) -> 85
A20: H_phys | B20: =IF(Input!$B$5,B19,B17) -> 80
A21: weak_ok | B21: =B20>=45 -> TRUE
A23: ATK
A24: buff_atk_plus | B24: =IF(Input!$B$20,15,0) +IF(Input!$B$21,6,0) +IF(Input!$B$22,9,0) +IF(Input!$B$23,5,0) +IF(Input!$B$24,7,0) +IF(Input!$B$25,10,0) +IF(Input!$B$26,10,0) +IF(Input!$B$27,9,0) -> 66
A25: skill_atk_plus | B25: =_xlfn.XLOOKUP("攻击|"&Input!$F$20,Skills!$A:$A,Skills!$G:$G,0) +_xlfn.XLOOKUP("挑战者|"&Input!$F$24,Skills!$A:$A,Skills!$G:$G,0)*Input!$B$10 +_xlfn.XLOOKUP("无伤|"&Input!$F$25,Skills!$A:$A,Skills!$G:$G,0)*Input!$B$11 +_xlfn.XLOOKUP("怨恨|"&Input!$F$26,Skills!$A:$A,Skills!$G:$G,0)*Input!$B$12 -> 17.5
A26: ATK_multi_eff | B26: =1 -> 1
A27: ATK_eff | B27: =(B2+B24+B25)*B26 -> 423.5
A29: 会心、CD、ECM
A30: CRT_plus | B30: =_xlfn.XLOOKUP("攻击|"&Input!$F$20,Skills!$A:$A,Skills!$I:$I,0) +_xlfn.XLOOKUP("看破|"&Input!$F$21,Skills!$A:$A,Skills!$I:$I,0) +IF(B21,IF(Input!$B$5,_xlfn.XLOOKUP("弱点特效|"&Input!$F$22,Skills!$A:$A,Skills!$L:$L,0),_xlfn.XLOOKUP("弱点特效|"&Input!$F$22,Skills!$A:$A,Skills!$K:$K,0))*Input!$B$9,0) +_xlfn.XLOOKUP("挑战者|"&Input!$F$24,Skills!$A:$A,Skills!$I:$I,0)*Input!$B$10 +_xlfn.XLOOKUP("力量解放|"&Input!$F$29,Skills!$A:$A,Skills!$I:$I,0)*Input!$B$13 +_xlfn.XLOOKUP("精神抖擞|"&Input!$F$30,Skills!$A:$A,Skills!$I:$I,0)*Input!$B$14 -> 0.2125
A31: CR_eff | B31: =B3+B30 -> -0.0875
A32: CR_eff_capped | B32: =MAX(-100%,MIN(100%,B31)) -> -0.0875
A33: CD | B33: =_xlfn.XLOOKUP("超会心|"&Input!$F$23,Skills!$A:$A,Skills!$J:$J,0) -> 1.3
A34: ECM | B34: =IF(B32>=0,1+B32*(B33-1),1+B32*0.25) -> 0.978125
A36: 集中 / 纳刀术有效帧数
A37: focus_reduce_per_charge | B37: =ROUNDDOWN(B13*_xlfn.XLOOKUP("集中|"&Input!$F$27,Skills!$A:$A,Skills!$M:$M,0),0) -> 0
A38: sheathe_reduce_per_sheathe | B38: =_xlfn.XLOOKUP("纳刀术|"&Input!$F$31,Skills!$A:$A,Skills!$N:$N,0) -> 0
A39: frames_eff | B39: =B11-B12*B37-B14*B38 -> 298
A41: 属性有效值
A42: ELE_eff | B42: =IF(B4=0,0,(B4+_xlfn.XLOOKUP("属性强化|"&Input!$F$28,Skills!$A:$A,Skills!$O:$O,0))*_xlfn.XLOOKUP("属性强化|"&Input!$F$28,Skills!$A:$A,Skills!$P:$P,1)) -> 180
A44: 伤害和 DPS
A45: D_phys | B45: =B9/100*B27*B5*B20/100*B34*Input!$B$6 -> 1499.2597
A46: D_ele | B46: =B10*B42/10*B6*B18/100 -> 25.65
A47: D_total | B47: =B45+B46 -> 1524.9097
...

Sheet Curve_Future
A1: skill | B1: current_level | C1: target_level | D1: add_levels | E1: max_level | F1: valid | G1: sim_attack | H1: sim_crit_eye | I1: sim_wex | J1: sim_crit_boost | K1: sim_agitator | L1: sim_peak | M1: sim_resentment | N1: sim_focus | O1: sim_ele_boost | P1: sim_latent_power | Q1: sim_max_might | R1: sim_sheathe | S1: ATK_eff_curve | T1: CR_eff_curve | U1: CR_eff_capped_curve | V1: CD_curve | W1: ECM_curve | X1: frames_eff_curve | Y1: ELE_eff_curve | Z1: D_phys_curve | AA1: D_ele_curve | AB1: D_total_curve | AC1: DPS_curve | AD1: gain_curve | AE1: label
A2: {=INDEX($AG$2:$AG$11,ROUNDUP(ROW(A1)/7,0))} -> 攻击 | B2: {=_xlfn.SWITCH(A2,"攻击",Input!$F$20,"看破",Input!$F$21,"弱点特效",Input!$F$22,"超会心",Input!$F$23,"挑战者",Input!$F$24,"无伤",Input!$F$25,"怨恨",Input!$F$26,"集中",Input!$F$27,"属性强化",Input!$F$28,"力量解放",Input!$F$29,"精神抖擞",Input!$F$30,"纳刀术",Input!$F$31)} -> 2 | C2: =B2+D2 -> 3 | D2: =MOD(ROW(A1)-1,7)+1 -> 1 | E2: =_xlfn.XLOOKUP(A2&"|0",Skills!$A:$A,Skills!$D:$D) -> 7 | F2: =AND(C2<=E2,_xlfn.XLOOKUP(A2&"|0",Skills!$A:$A,Skills!$F:$F)=TRUE) -> TRUE | G2: =IF($A2="攻击",$C2,Input!$F$20) -> 3 | H2: =IF($A2="看破",$C2,Input!$F$21) -> 2 | I2: =IF($A2="弱点特效",$C2,Input!$F$22) -> 1 | J2: =IF($A2="超会心",$C2,Input!$F$23) -> 1 | K2: =IF($A2="挑战者",$C2,Input!$F$24) -> 3 | L2: =IF($A2="无伤",$C2,Input!$F$25) -> 1 | M2: =IF($A2="怨恨",$C2,Input!$F$26) -> 0 | N2: =IF($A2="集中",$C2,Input!$F$27) -> 0 | O2: =IF($A2="属性强化",$C2,Input!$F$28) -> 0 | P2: =Input!$F$29 -> 0 | Q2: =Input!$F$30 -> 0 | R2: =IF($A2="纳刀术",$C2,Input!$F$31) -> 0 | S2: =(Calc_Current!$B$2+Calc_Current!$B$24+_xlfn.XLOOKUP("攻击|"&G2,Skills!$A:$A,Skills!$G:$G,0)+_xlfn.XLOOKUP("挑战者|"&K2,Skills!$A:$A,Skills!$G:$G,0)*Input!$B$10+_xlfn.XLOOKUP("无伤|"&L2,Skills!$A:$A,Skills!$G:$G,0)*Input!$B$11+_xlfn.XLOOKUP("怨恨|"&M2,Skills!$A:$A,Skills!$G:$G,0)*Input!$B$12)*Calc_Current!$B$26 -> 426.5 | T2: =Calc_Current!$B$3+_xlfn.XLOOKUP("攻击|"&G2,Skills!$A:$A,Skills!$I:$I,0)+_xlfn.XLOOKUP("看破|"&H2,Skills!$A:$A,Skills!$I:$I,0)+IF(Calc_Current!$B$21,IF(Input!$B$5,_xlfn.XLOOKUP("弱点特效|"&I2,Skills!$A:$A,Skills!$L:$L,0),_xlfn.XLOOKUP("弱点特效|"&I2,Skills!$A:$A,Skills!$K:$K,0))*Input!$B$9,0)+_xlfn.XLOOKUP("挑战者|"&K2,Skills!$A:$A,Skills!$I:$I,0)*Input!$B$10+_xlfn.XLOOKUP("力量解放|"&P2,Skills!$A:$A,Skills!$I:$I,0)*Input!$B$13+_xlfn.XLOOKUP("精神抖擞|"&Q2,Skills!$A:$A,Skills!$I:$I,0)*Input!$B$14 -> -0.0875 | U2: =MAX(-100%,MIN(100%,T2)) -> -0.0875 | V2: =_xlfn.XLOOKUP("超会心|"&J2,Skills!$A:$A,Skills!$J:$J,1.25) -> 1.3 | W2: =IF(U2>=0,1+U2*(V2-1),1+U2*0.25) -> 0.978125 | X2: =Calc_Current!$B$11-Calc_Current!$B$12*ROUNDDOWN(Calc_Current!$B$13*_xlfn.XLOOKUP("集中|"&N2,Skills!$A:$A,Skills!$M:$M,0),0)-Calc_Current!$B$14*_xlfn.XLOOKUP("纳刀术|"&R2,Skills!$A:$A,Skills!$N:$N,0) -> 298 | Y2: =IF(Calc_Current!$B$4=0,0,(Calc_Current!$B$4+_xlfn.XLOOKUP("属性强化|"&O2,Skills!$A:$A,Skills!$O:$O,0))*_xlfn.XLOOKUP("属性强化|"&O2,Skills!$A:$A,Skills!$P:$P,1)) -> 180 | Z2: =Calc_Current!$B$9/100*S2*Calc_Current!$B$5*Calc_Current!$B$20/100*W2*Input!$B$6 -> 1509.8802 | AA2: =Calc_Current!$B$10*Y2/10*Calc_Current!$B$6*Calc_Current!$B$18/100 -> 25.65 | AB2: =Z2+AA2 -> 1535.5302 | AC2: =IF(F2,AB2*30/X2,NA()) -> 154.58358 | AD2: =IF(F2,AC2/Calc_Current!$B$48-1,NA()) -> 0.0069646706 | AE2: =A2&" "&B2&"→"&C2 -> 攻击 2→3 | AG2: 攻击
A3: {=INDEX($AG$2:$AG$11,ROUNDUP(ROW(A2)/7,0))} -> 攻击 | B3: {=_xlfn.SWITCH(A3,"攻击",Input!$F$20,"看破",Input!$F$21,"弱点特效",Input!$F$22,"超会心",Input!$F$23,"挑战者",Input!$F$24,"无伤",Input!$F$25,"怨恨",Input!$F$26,"集中",Input!$F$27,"属性强化",Input!$F$28,"力量解放",Input!$F$29,"精神抖擞",Input!$F$30,"纳刀术",Input!$F$31)} -> 2 | C3: =B3+D3 -> 4 | D3: =MOD(ROW(A2)-1,7)+1 -> 2 | E3: =_xlfn.XLOOKUP(A3&"|0",Skills!$A:$A,Skills!$D:$D) -> 7 | F3: =AND(C3<=E3,_xlfn.XLOOKUP(A3&"|0",Skills!$A:$A,Skills!$F:$F)=TRUE) -> TRUE | G3: =IF($A3="攻击",$C3,Input!$F$20) -> 4 | H3: =IF($A3="看破",$C3,Input!$F$21) -> 2 | I3: =IF($A3="弱点特效",$C3,Input!$F$22) -> 1 | J3: =IF($A3="超会心",$C3,Input!$F$23) -> 1 | K3: =IF($A3="挑战者",$C3,Input!$F$24) -> 3 | L3: =IF($A3="无伤",$C3,Input!$F$25) -> 1 | M3: =IF($A3="怨恨",$C3,Input!$F$26) -> 0 | N3: =IF($A3="集中",$C3,Input!$F$27) -> 0 | O3: =IF($A3="属性强化",$C3,Input!$F$28) -> 0 | P3: =Input!$F$29 -> 0 | Q3: =Input!$F$30 -> 0 | R3: =IF($A3="纳刀术",$C3,Input!$F$31) -> 0 | S3: =(Calc_Current!$B$2+Calc_Current!$B$24+_xlfn.XLOOKUP("攻击|"&G3,Skills!$A:$A,Skills!$G:$G,0)+_xlfn.XLOOKUP("挑战者|"&K3,Skills!$A:$A,Skills!$G:$G,0)*Input!$B$10+_xlfn.XLOOKUP("无伤|"&L3,Skills!$A:$A,Skills!$G:$G,0)*Input!$B$11+_xlfn.XLOOKUP("怨恨|"&M3,Skills!$A:$A,Skills!$G:$G,0)*Input!$B$12)*Calc_Current!$B$26 -> 429.5 | T3: =Calc_Current!$B$3+_xlfn.XLOOKUP("攻击|"&G3,Skills!$A:$A,Skills!$I:$I,0)+_xlfn.XLOOKUP("看破|"&H3,Skills!$A:$A,Skills!$I:$I,0)+IF(Calc_Current!$B$21,IF(Input!$B$5,_xlfn.XLOOKUP("弱点特效|"&I3,Skills!$A:$A,Skills!$L:$L,0),_xlfn.XLOOKUP("弱点特效|"&I3,Skills!$A:$A,Skills!$K:$K,0))*Input!$B$9,0)+_xlfn.XLOOKUP("挑战者|"&K3,Skills!$A:$A,Skills!$I:$I,0)*Input!$B$10+_xlfn.XLOOKUP("力量解放|"&P3,Skills!$A:$A,Skills!$I:$I,0)*Input!$B$13+_xlfn.XLOOKUP("精神抖擞|"&Q3,Skills!$A:$A,Skills!$I:$I,0)*Input!$B$14 -> -0.0375 | U3: =MAX(-100%,MIN(100%,T3)) -> -0.0375 | V3: =_xlfn.XLOOKUP("超会心|"&J3,Skills!$A:$A,Skills!$J:$J,1.25) -> 1.3 | W3: =IF(U3>=0,1+U3*(V3-1),1+U3*0.25) -> 0.990625 | X3: =Calc_Current!$B$11-Calc_Current!$B$12*ROUNDDOWN(Calc_Current!$B$13*_xlfn.XLOOKUP("集中|"&N3,Skills!$A:$A,Skills!$M:$M,0),0)-Calc_Current!$B$14*_xlfn.XLOOKUP("纳刀术|"&R3,Skills!$A:$A,Skills!$N:$N,0) -> 298 | Y3: =IF(Calc_Current!$B$4=0,0,(Calc_Current!$B$4+_xlfn.XLOOKUP("属性强化|"&O3,Skills!$A:$A,Skills!$O:$O,0))*_xlfn.XLOOKUP("属性强化|"&O3,Skills!$A:$A,Skills!$P:$P,1)) -> 180 | Z3: =Calc_Current!$B$9/100*S3*Calc_Current!$B$5*Calc_Current!$B$20/100*W3*Input!$B$6 -> 1539.932 | AA3: =Calc_Current!$B$10*Y3/10*Calc_Current!$B$6*Calc_Current!$B$18/100 -> 25.65 | AB3: =Z3+AA3 -> 1565.582 | AC3: =IF(F3,AB3*30/X3,NA()) -> 157.60893 | AD3: =IF(F3,AC3/Calc_Current!$B$48-1,NA()) -> 0.026671944 | AE3: =A3&" "&B3&"→"&C3 -> 攻击 2→4 | AG3: 看破
A4: {=INDEX($AG$2:$AG$11,ROUNDUP(ROW(A3)/7,0))} -> 攻击 | B4: {=_xlfn.SWITCH(A4,"攻击",Input!$F$20,"看破",Input!$F$21,"弱点特效",Input!$F$22,"超会心",Input!$F$23,"挑战者",Input!$F$24,"无伤",Input!$F$25,"怨恨",Input!$F$26,"集中",Input!$F$27,"属性强化",Input!$F$28,"力量解放",Input!$F$29,"精神抖擞",Input!$F$30,"纳刀术",Input!$F$31)} -> 2 | C4: =B4+D4 -> 5 | D4: =MOD(ROW(A3)-1,7)+1 -> 3 | E4: =_xlfn.XLOOKUP(A4&"|0",Skills!$A:$A,Skills!$D:$D) -> 7 | F4: =AND(C4<=E4,_xlfn.XLOOKUP(A4&"|0",Skills!$A:$A,Skills!$F:$F)=TRUE) -> TRUE | G4: =IF($A4="攻击",$C4,Input!$F$20) -> 5 | H4: =IF($A4="看破",$C4,Input!$F$21) -> 2 | I4: =IF($A4="弱点特效",$C4,Input!$F$22) -> 1 | J4: =IF($A4="超会心",$C4,Input!$F$23) -> 1 | K4: =IF($A4="挑战者",$C4,Input!$F$24) -> 3 | L4: =IF($A4="无伤",$C4,Input!$F$25) -> 1 | M4: =IF($A4="怨恨",$C4,Input!$F$26) -> 0 | N4: =IF($A4="集中",$C4,Input!$F$27) -> 0 | O4: =IF($A4="属性强化",$C4,Input!$F$28) -> 0 | P4: =Input!$F$29 -> 0 | Q4: =Input!$F$30 -> 0 | R4: =IF($A4="纳刀术",$C4,Input!$F$31) -> 0 | S4: =(Calc_Current!$B$2+Calc_Current!$B$24+_xlfn.XLOOKUP("攻击|"&G4,Skills!$A:$A,Skills!$G:$G,0)+_xlfn.XLOOKUP("挑战者|"&K4,Skills!$A:$A,Skills!$G:$G,0)*Input!$B$10+_xlfn.XLOOKUP("无伤|"&L4,Skills!$A:$A,Skills!$G:$G,0)*Input!$B$11+_xlfn.XLOOKUP("怨恨|"&M4,Skills!$A:$A,Skills!$G:$G,0)*Input!$B$12)*Calc_Current!$B$26 -> 432.5 | T4: =Calc_Current!$B$3+_xlfn.XLOOKUP("攻击|"&G4,Skills!$A:$A,Skills!$I:$I,0)+_xlfn.XLOOKUP("看破|"&H4,Skills!$A:$A,Skills!$I:$I,0)+IF(Calc_Current!$B$21,IF(Input!$B$5,_xlfn.XLOOKUP("弱点特效|"&I4,Skills!$A:$A,Skills!$L:$L,0),_xlfn.XLOOKUP("弱点特效|"&I4,Skills!$A:$A,Skills!$K:$K,0))*Input!$B$9,0)+_xlfn.XLOOKUP("挑战者|"&K4,Skills!$A:$A,Skills!$I:$I,0)*Input!$B$10+_xlfn.XLOOKUP("力量解放|"&P4,Skills!$A:$A,Skills!$I:$I,0)*Input!$B$13+_xlfn.XLOOKUP("精神抖擞|"&Q4,Skills!$A:$A,Skills!$I:$I,0)*Input!$B$14 -> -0.0375 | U4: =MAX(-100%,MIN(100%,T4)) -> -0.0375 | V4: =_xlfn.XLOOKUP("超会心|"&J4,Skills!$A:$A,Skills!$J:$J,1.25) -> 1.3 | W4: =IF(U4>=0,1+U4*(V4-1),1+U4*0.25) -> 0.990625 | X4: =Calc_Current!$B$11-Calc_Current!$B$12*ROUNDDOWN(Calc_Current!$B$13*_xlfn.XLOOKUP("集中|"&N4,Skills!$A:$A,Skills!$M:$M,0),0)-Calc_Current!$B$14*_xlfn.XLOOKUP("纳刀术|"&R4,Skills!$A:$A,Skills!$N:$N,0) -> 298 | Y4: =IF(Calc_Current!$B$4=0,0,(Calc_Current!$B$4+_xlfn.XLOOKUP("属性强化|"&O4,Skills!$A:$A,Skills!$O:$O,0))*_xlfn.XLOOKUP("属性强化|"&O4,Skills!$A:$A,Skills!$P:$P,1)) -> 180 | Z4: =Calc_Current!$B$9/100*S4*Calc_Current!$B$5*Calc_Current!$B$20/100*W4*Input!$B$6 -> 1550.6882 | AA4: =Calc_Current!$B$10*Y4/10*Calc_Current!$B$6*Calc_Current!$B$18/100 -> 25.65 | AB4: =Z4+AA4 -> 1576.3382 | AC4: =IF(F4,AB4*30/X4,NA()) -> 158.69177 | AD4: =IF(F4,AC4/Calc_Current!$B$48-1,NA()) -> 0.03372562 | AE4: =A4&" "&B4&"→"&C4 -> 攻击 2→5 | AG4: 弱点特效
A5: {=INDEX($AG$2:$AG$11,ROUNDUP(ROW(A4)/7,0))} -> 攻击 | B5: {=_xlfn.SWITCH(A5,"攻击",Input!$F$20,"看破",Input!$F$21,"弱点特效",Input!$F$22,"超会心",Input!$F$23,"挑战者",Input!$F$24,"无伤",Input!$F$25,"怨恨",Input!$F$26,"集中",Input!$F$27,"属性强化",Input!$F$28,"力量解放",Input!$F$29,"精神抖擞",Input!$F$30,"纳刀术",Input!$F$31)} -> 2 | C5: =B5+D5 -> 6 | D5: =MOD(ROW(A4)-1,7)+1 -> 4 | E5: =_xlfn.XLOOKUP(A5&"|0",Skills!$A:$A,Skills!$D:$D) -> 7 | F5: =AND(C5<=E5,_xlfn.XLOOKUP(A5&"|0",Skills!$A:$A,Skills!$F:$F)=TRUE) -> TRUE | G5: =IF($A5="攻击",$C5,Input!$F$20) -> 6 | H5: =IF($A5="看破",$C5,Input!$F$21) -> 2 | I5: =IF($A5="弱点特效",$C5,Input!$F$22) -> 1 | J5: =IF($A5="超会心",$C5,Input!$F$23) -> 1 | K5: =IF($A5="挑战者",$C5,Input!$F$24) -> 3 | L5: =IF($A5="无伤",$C5,Input!$F$25) -> 1 | M5: =IF($A5="怨恨",$C5,Input!$F$26) -> 0 | N5: =IF($A5="集中",$C5,Input!$F$27) -> 0 | O5: =IF($A5="属性强化",$C5,Input!$F$28) -> 0 | P5: =Input!$F$29 -> 0 | Q5: =Input!$F$30 -> 0 | R5: =IF($A5="纳刀术",$C5,Input!$F$31) -> 0 | S5: =(Calc_Current!$B$2+Calc_Current!$B$24+_xlfn.XLOOKUP("攻击|"&G5,Skills!$A:$A,Skills!$G:$G,0)+_xlfn.XLOOKUP("挑战者|"&K5,Skills!$A:$A,Skills!$G:$G,0)*Input!$B$10+_xlfn.XLOOKUP("无伤|"&L5,Skills!$A:$A,Skills!$G:$G,0)*Input!$B$11+_xlfn.XLOOKUP("怨恨|"&M5,Skills!$A:$A,Skills!$G:$G,0)*Input!$B$12)*Calc_Current!$B$26 -> 435.5 | T5: =Calc_Current!$B$3+_xlfn.XLOOKUP("攻击|"&G5,Skills!$A:$A,Skills!$I:$I,0)+_xlfn.XLOOKUP("看破|"&H5,Skills!$A:$A,Skills!$I:$I,0)+IF(Calc_Current!$B$21,IF(Input!$B$5,_xlfn.XLOOKUP("弱点特效|"&I5,Skills!$A:$A,Skills!$L:$L,0),_xlfn.XLOOKUP("弱点特效|"&I5,Skills!$A:$A,Skills!$K:$K,0))*Input!$B$9,0)+_xlfn.XLOOKUP("挑战者|"&K5,Skills!$A:$A,Skills!$I:$I,0)*Input!$B$10+_xlfn.XLOOKUP("力量解放|"&P5,Skills!$A:$A,Skills!$I:$I,0)*Input!$B$13+_xlfn.XLOOKUP("精神抖擞|"&Q5,Skills!$A:$A,Skills!$I:$I,0)*Input!$B$14 -> -0.0375 | U5: =MAX(-100%,MIN(100%,T5)) -> -0.0375 | V5: =_xlfn.XLOOKUP("超会心|"&J5,Skills!$A:$A,Skills!$J:$J,1.25) -> 1.3 | W5: =IF(U5>=0,1+U5*(V5-1),1+U5*0.25) -> 0.990625 | X5: =Calc_Current!$B$11-Calc_Current!$B$12*ROUNDDOWN(Calc_Current!$B$13*_xlfn.XLOOKUP("集中|"&N5,Skills!$A:$A,Skills!$M:$M,0),0)-Calc_Current!$B$14*_xlfn.XLOOKUP("纳刀术|"&R5,Skills!$A:$A,Skills!$N:$N,0) -> 298 | Y5: =IF(Calc_Current!$B$4=0,0,(Calc_Current!$B$4+_xlfn.XLOOKUP("属性强化|"&O5,Skills!$A:$A,Skills!$O:$O,0))*_xlfn.XLOOKUP("属性强化|"&O5,Skills!$A:$A,Skills!$P:$P,1)) -> 180 | Z5: =Calc_Current!$B$9/100*S5*Calc_Current!$B$5*Calc_Current!$B$20/100*W5*Input!$B$6 -> 1561.4444 | AA5: =Calc_Current!$B$10*Y5/10*Calc_Current!$B$6*Calc_Current!$B$18/100 -> 25.65 | AB5: =Z5+AA5 -> 1587.0944 | AC5: =IF(F5,AB5*30/X5,NA()) -> 159.77461 | AD5: =IF(F5,AC5/Calc_Current!$B$48-1,NA()) -> 0.040779296 | AE5: =A5&" "&B5&"→"&C5 -> 攻击 2→6 | AG5: 超会心
A6: {=INDEX($AG$2:$AG$11,ROUNDUP(ROW(A5)/7,0))} -> 攻击 | B6: {=_xlfn.SWITCH(A6,"攻击",Input!$F$20,"看破",Input!$F$21,"弱点特效",Input!$F$22,"超会心",Input!$F$23,"挑战者",Input!$F$24,"无伤",Input!$F$25,"怨恨",Input!$F$26,"集中",Input!$F$27,"属性强化",Input!$F$28,"力量解放",Input!$F$29,"精神抖擞",Input!$F$30,"纳刀术",Input!$F$31)} -> 2 | C6: =B6+D6 -> 7 | D6: =MOD(ROW(A5)-1,7)+1 -> 5 | E6: =_xlfn.XLOOKUP(A6&"|0",Skills!$A:$A,Skills!$D:$D) -> 7 | F6: =AND(C6<=E6,_xlfn.XLOOKUP(A6&"|0",Skills!$A:$A,Skills!$F:$F)=TRUE) -> TRUE | G6: =IF($A6="攻击",$C6,Input!$F$20) -> 7 | H6: =IF($A6="看破",$C6,Input!$F$21) -> 2 | I6: =IF($A6="弱点特效",$C6,Input!$F$22) -> 1 | J6: =IF($A6="超会心",$C6,Input!$F$23) -> 1 | K6: =IF($A6="挑战者",$C6,Input!$F$24) -> 3 | L6: =IF($A6="无伤",$C6,Input!$F$25) -> 1 | M6: =IF($A6="怨恨",$C6,Input!$F$26) -> 0 | N6: =IF($A6="集中",$C6,Input!$F$27) -> 0 | O6: =IF($A6="属性强化",$C6,Input!$F$28) -> 0 | P6: =Input!$F$29 -> 0 | Q6: =Input!$F$30 -> 0 | R6: =IF($A6="纳刀术",$C6,Input!$F$31) -> 0 | S6: =(Calc_Current!$B$2+Calc_Current!$B$24+_xlfn.XLOOKUP("攻击|"&G6,Skills!$A:$A,Skills!$G:$G,0)+_xlfn.XLOOKUP("挑战者|"&K6,Skills!$A:$A,Skills!$G:$G,0)*Input!$B$10+_xlfn.XLOOKUP("无伤|"&L6,Skills!$A:$A,Skills!$G:$G,0)*Input!$B$11+_xlfn.XLOOKUP("怨恨|"&M6,Skills!$A:$A,Skills!$G:$G,0)*Input!$B$12)*Calc_Current!$B$26 -> 438.5 | T6: =Calc_Current!$B$3+_xlfn.XLOOKUP("攻击|"&G6,Skills!$A:$A,Skills!$I:$I,0)+_xlfn.XLOOKUP("看破|"&H6,Skills!$A:$A,Skills!$I:$I,0)+IF(Calc_Current!$B$21,IF(Input!$B$5,_xlfn.XLOOKUP("弱点特效|"&I6,Skills!$A:$A,Skills!$L:$L,0),_xlfn.XLOOKUP("弱点特效|"&I6,Skills!$A:$A,Skills!$K:$K,0))*Input!$B$9,0)+_xlfn.XLOOKUP("挑战者|"&K6,Skills!$A:$A,Skills!$I:$I,0)*Input!$B$10+_xlfn.XLOOKUP("力量解放|"&P6,Skills!$A:$A,Skills!$I:$I,0)*Input!$B$13+_xlfn.XLOOKUP("精神抖擞|"&Q6,Skills!$A:$A,Skills!$I:$I,0)*Input!$B$14 -> -0.0375 | U6: =MAX(-100%,MIN(100%,T6)) -> -0.0375 | V6: =_xlfn.XLOOKUP("超会心|"&J6,Skills!$A:$A,Skills!$J:$J,1.25) -> 1.3 | W6: =IF(U6>=0,1+U6*(V6-1),1+U6*0.25) -> 0.990625 | X6: =Calc_Current!$B$11-Calc_Current!$B$12*ROUNDDOWN(Calc_Current!$B$13*_xlfn.XLOOKUP("集中|"&N6,Skills!$A:$A,Skills!$M:$M,0),0)-Calc_Current!$B$14*_xlfn.XLOOKUP("纳刀术|"&R6,Skills!$A:$A,Skills!$N:$N,0) -> 298 | Y6: =IF(Calc_Current!$B$4=0,0,(Calc_Current!$B$4+_xlfn.XLOOKUP("属性强化|"&O6,Skills!$A:$A,Skills!$O:$O,0))*_xlfn.XLOOKUP("属性强化|"&O6,Skills!$A:$A,Skills!$P:$P,1)) -> 180 | Z6: =Calc_Current!$B$9/100*S6*Calc_Current!$B$5*Calc_Current!$B$20/100*W6*Input!$B$6 -> 1572.2007 | AA6: =Calc_Current!$B$10*Y6/10*Calc_Current!$B$6*Calc_Current!$B$18/100 -> 25.65 | AB6: =Z6+AA6 -> 1597.8507 | AC6: =IF(F6,AB6*30/X6,NA()) -> 160.85745 | AD6: =IF(F6,AC6/Calc_Current!$B$48-1,NA()) -> 0.047832972 | AE6: =A6&" "&B6&"→"&C6 -> 攻击 2→7 | AG6: 挑战者
A7: {=INDEX($AG$2:$AG$11,ROUNDUP(ROW(A6)/7,0))} -> 攻击 | B7: {=_xlfn.SWITCH(A7,"攻击",Input!$F$20,"看破",Input!$F$21,"弱点特效",Input!$F$22,"超会心",Input!$F$23,"挑战者",Input!$F$24,"无伤",Input!$F$25,"怨恨",Input!$F$26,"集中",Input!$F$27,"属性强化",Input!$F$28,"力量解放",Input!$F$29,"精神抖擞",Input!$F$30,"纳刀术",Input!$F$31)} -> 2 | C7: =B7+D7 -> 8 | D7: =MOD(ROW(A6)-1,7)+1 -> 6 | E7: =_xlfn.XLOOKUP(A7&"|0",Skills!$A:$A,Skills!$D:$D) -> 7 | F7: =AND(C7<=E7,_xlfn.XLOOKUP(A7&"|0",Skills!$A:$A,Skills!$F:$F)=TRUE) -> FALSE | G7: =IF($A7="攻击",$C7,Input!$F$20) -> 8 | H7: =IF($A7="看破",$C7,Input!$F$21) -> 2 | I7: =IF($A7="弱点特效",$C7,Input!$F$22) -> 1 | J7: =IF($A7="超会心",$C7,Input!$F$23) -> 1 | K7: =IF($A7="挑战者",$C7,Input!$F$24) -> 3 | L7: =IF($A7="无伤",$C7,Input!$F$25) -> 1 | M7: =IF($A7="怨恨",$C7,Input!$F$26) -> 0 | N7: =IF($A7="集中",$C7,Input!$F$27) -> 0 | O7: =IF($A7="属性强化",$C7,Input!$F$28) -> 0 | P7: =Input!$F$29 -> 0 | Q7: =Input!$F$30 -> 0 | R7: =IF($A7="纳刀术",$C7,Input!$F$31) -> 0 | S7: =(Calc_Current!$B$2+Calc_Current!$B$24+_xlfn.XLOOKUP("攻击|"&G7,Skills!$A:$A,Skills!$G:$G,0)+_xlfn.XLOOKUP("挑战者|"&K7,Skills!$A:$A,Skills!$G:$G,0)*Input!$B$10+_xlfn.XLOOKUP("无伤|"&L7,Skills!$A:$A,Skills!$G:$G,0)*Input!$B$11+_xlfn.XLOOKUP("怨恨|"&M7,Skills!$A:$A,Skills!$G:$G,0)*Input!$B$12)*Calc_Current!$B$26 -> 417.5 | T7: =Calc_Current!$B$3+_xlfn.XLOOKUP("攻击|"&G7,Skills!$A:$A,Skills!$I:$I,0)+_xlfn.XLOOKUP("看破|"&H7,Skills!$A:$A,Skills!$I:$I,0)+IF(Calc_Current!$B$21,IF(Input!$B$5,_xlfn.XLOOKUP("弱点特效|"&I7,Skills!$A:$A,Skills!$L:$L,0),_xlfn.XLOOKUP("弱点特效|"&I7,Skills!$A:$A,Skills!$K:$K,0))*Input!$B$9,0)+_xlfn.XLOOKUP("挑战者|"&K7,Skills!$A:$A,Skills!$I:$I,0)*Input!$B$10+_xlfn.XLOOKUP("力量解放|"&P7,Skills!$A:$A,Skills!$I:$I,0)*Input!$B$13+_xlfn.XLOOKUP("精神抖擞|"&Q7,Skills!$A:$A,Skills!$I:$I,0)*Input!$B$14 -> -0.0875 | U7: =MAX(-100%,MIN(100%,T7)) -> -0.0875 | V7: =_xlfn.XLOOKUP("超会心|"&J7,Skills!$A:$A,Skills!$J:$J,1.25) -> 1.3 | W7: =IF(U7>=0,1+U7*(V7-1),1+U7*0.25) -> 0.978125 | X7: =Calc_Current!$B$11-Calc_Current!$B$12*ROUNDDOWN(Calc_Current!$B$13*_xlfn.XLOOKUP("集中|"&N7,Skills!$A:$A,Skills!$M:$M,0),0)-Calc_Current!$B$14*_xlfn.XLOOKUP("纳刀术|"&R7,Skills!$A:$A,Skills!$N:$N,0) -> 298 | Y7: =IF(Calc_Current!$B$4=0,0,(Calc_Current!$B$4+_xlfn.XLOOKUP("属性强化|"&O7,Skills!$A:$A,Skills!$O:$O,0))*_xlfn.XLOOKUP("属性强化|"&O7,Skills!$A:$A,Skills!$P:$P,1)) -> 180 | Z7: =Calc_Current!$B$9/100*S7*Calc_Current!$B$5*Calc_Current!$B$20/100*W7*Input!$B$6 -> 1478.0187 | AA7: =Calc_Current!$B$10*Y7/10*Calc_Current!$B$6*Calc_Current!$B$18/100 -> 25.65 | AB7: =Z7+AA7 -> 1503.6687 | AC7: =IF(F7,AB7*30/X7,NA()) -> #N/A | AD7: =IF(F7,AC7/Calc_Current!$B$48-1,NA()) -> #N/A | AE7: =A7&" "&B7&"→"&C7 -> 攻击 2→8 | AG7: 无伤
A8: {=INDEX($AG$2:$AG$11,ROUNDUP(ROW(A7)/7,0))} -> 攻击 | B8: {=_xlfn.SWITCH(A8,"攻击",Input!$F$20,"看破",Input!$F$21,"弱点特效",Input!$F$22,"超会心",Input!$F$23,"挑战者",Input!$F$24,"无伤",Input!$F$25,"怨恨",Input!$F$26,"集中",Input!$F$27,"属性强化",Input!$F$28,"力量解放",Input!$F$29,"精神抖擞",Input!$F$30,"纳刀术",Input!$F$31)} -> 2 | C8: =B8+D8 -> 9 | D8: =MOD(ROW(A7)-1,7)+1 -> 7 | E8: =_xlfn.XLOOKUP(A8&"|0",Skills!$A:$A,Skills!$D:$D) -> 7 | F8: =AND(C8<=E8,_xlfn.XLOOKUP(A8&"|0",Skills!$A:$A,Skills!$F:$F)=TRUE) -> FALSE | G8: =IF($A8="攻击",$C8,Input!$F$20) -> 9 | H8: =IF($A8="看破",$C8,Input!$F$21) -> 2 | I8: =IF($A8="弱点特效",$C8,Input!$F$22) -> 1 | J8: =IF($A8="超会心",$C8,Input!$F$23) -> 1 | K8: =IF($A8="挑战者",$C8,Input!$F$24) -> 3 | L8: =IF($A8="无伤",$C8,Input!$F$25) -> 1 | M8: =IF($A8="怨恨",$C8,Input!$F$26) -> 0 | N8: =IF($A8="集中",$C8,Input!$F$27) -> 0 | O8: =IF($A8="属性强化",$C8,Input!$F$28) -> 0 | P8: =Input!$F$29 -> 0 | Q8: =Input!$F$30 -> 0 | R8: =IF($A8="纳刀术",$C8,Input!$F$31) -> 0 | S8: =(Calc_Current!$B$2+Calc_Current!$B$24+_xlfn.XLOOKUP("攻击|"&G8,Skills!$A:$A,Skills!$G:$G,0)+_xlfn.XLOOKUP("挑战者|"&K8,Skills!$A:$A,Skills!$G:$G,0)*Input!$B$10+_xlfn.XLOOKUP("无伤|"&L8,Skills!$A:$A,Skills!$G:$G,0)*Input!$B$11+_xlfn.XLOOKUP("怨恨|"&M8,Skills!$A:$A,Skills!$G:$G,0)*Input!$B$12)*Calc_Current!$B$26 -> 417.5 | T8: =Calc_Current!$B$3+_xlfn.XLOOKUP("攻击|"&G8,Skills!$A:$A,Skills!$I:$I,0)+_xlfn.XLOOKUP("看破|"&H8,Skills!$A:$A,Skills!$I:$I,0)+IF(Calc_Current!$B$21,IF(Input!$B$5,_xlfn.XLOOKUP("弱点特效|"&I8,Skills!$A:$A,Skills!$L:$L,0),_xlfn.XLOOKUP("弱点特效|"&I8,Skills!$A:$A,Skills!$K:$K,0))*Input!$B$9,0)+_xlfn.XLOOKUP("挑战者|"&K8,Skills!$A:$A,Skills!$I:$I,0)*Input!$B$10+_xlfn.XLOOKUP("力量解放|"&P8,Skills!$A:$A,Skills!$I:$I,0)*Input!$B$13+_xlfn.XLOOKUP("精神抖擞|"&Q8,Skills!$A:$A,Skills!$I:$I,0)*Input!$B$14 -> -0.0875 | U8: =MAX(-100%,MIN(100%,T8)) -> -0.0875 | V8: =_xlfn.XLOOKUP("超会心|"&J8,Skills!$A:$A,Skills!$J:$J,1.25) -> 1.3 | W8: =IF(U8>=0,1+U8*(V8-1),1+U8*0.25) -> 0.978125 | X8: =Calc_Current!$B$11-Calc_Current!$B$12*ROUNDDOWN(Calc_Current!$B$13*_xlfn.XLOOKUP("集中|"&N8,Skills!$A:$A,Skills!$M:$M,0),0)-Calc_Current!$B$14*_xlfn.XLOOKUP("纳刀术|"&R8,Skills!$A:$A,Skills!$N:$N,0) -> 298 | Y8: =IF(Calc_Current!$B$4=0,0,(Calc_Current!$B$4+_xlfn.XLOOKUP("属性强化|"&O8,Skills!$A:$A,Skills!$O:$O,0))*_xlfn.XLOOKUP("属性强化|"&O8,Skills!$A:$A,Skills!$P:$P,1)) -> 180 | Z8: =Calc_Current!$B$9/100*S8*Calc_Current!$B$5*Calc_Current!$B$20/100*W8*Input!$B$6 -> 1478.0187 | AA8: =Calc_Current!$B$10*Y8/10*Calc_Current!$B$6*Calc_Current!$B$18/100 -> 25.65 | AB8: =Z8+AA8 -> 1503.6687 | AC8: =IF(F8,AB8*30/X8,NA()) -> #N/A | AD8: =IF(F8,AC8/Calc_Current!$B$48-1,NA()) -> #N/A | AE8: =A8&" "&B8&"→"&C8 -> 攻击 2→9 | AG8: 怨恨
A9: {=INDEX($AG$2:$AG$11,ROUNDUP(ROW(A8)/7,0))} -> 看破 | B9: {=_xlfn.SWITCH(A9,"攻击",Input!$F$20,"看破",Input!$F$21,"弱点特效",Input!$F$22,"超会心",Input!$F$23,"挑战者",Input!$F$24,"无伤",Input!$F$25,"怨恨",Input!$F$26,"集中",Input!$F$27,"属性强化",Input!$F$28,"力量解放",Input!$F$29,"精神抖擞",Input!$F$30,"纳刀术",Input!$F$31)} -> 2 | C9: =B9+D9 -> 3 | D9: =MOD(ROW(A8)-1,7)+1 -> 1 | E9: =_xlfn.XLOOKUP(A9&"|0",Skills!$A:$A,Skills!$D:$D) -> 7 | F9: =AND(C9<=E9,_xlfn.XLOOKUP(A9&"|0",Skills!$A:$A,Skills!$F:$F)=TRUE) -> TRUE | G9: =IF($A9="攻击",$C9,Input!$F$20) -> 2 | H9: =IF($A9="看破",$C9,Input!$F$21) -> 3 | I9: =IF($A9="弱点特效",$C9,Input!$F$22) -> 1 | J9: =IF($A9="超会心",$C9,Input!$F$23) -> 1 | K9: =IF($A9="挑战者",$C9,Input!$F$24) -> 3 | L9: =IF($A9="无伤",$C9,Input!$F$25) -> 1 | M9: =IF($A9="怨恨",$C9,Input!$F$26) -> 0 | N9: =IF($A9="集中",$C9,Input!$F$27) -> 0 | O9: =IF($A9="属性强化",$C9,Input!$F$28) -> 0 | P9: =Input!$F$29 -> 0 | Q9: =Input!$F$30 -> 0 | R9: =IF($A9="纳刀术",$C9,Input!$F$31) -> 0 | S9: =(Calc_Current!$B$2+Calc_Current!$B$24+_xlfn.XLOOKUP("攻击|"&G9,Skills!$A:$A,Skills!$G:$G,0)+_xlfn.XLOOKUP("挑战者|"&K9,Skills!$A:$A,Skills!$G:$G,0)*Input!$B$10+_xlfn.XLOOKUP("无伤|"&L9,Skills!$A:$A,Skills!$G:$G,0)*Input!$B$11+_xlfn.XLOOKUP("怨恨|"&M9,Skills!$A:$A,Skills!$G:$G,0)*Input!$B$12)*Calc_Current!$B$26 -> 423.5 | T9: =Calc_Current!$B$3+_xlfn.XLOOKUP("攻击|"&G9,Skills!$A:$A,Skills!$I:$I,0)+_xlfn.XLOOKUP("看破|"&H9,Skills!$A:$A,Skills!$I:$I,0)+IF(Calc_Current!$B$21,IF(Input!$B$5,_xlfn.XLOOKUP("弱点特效|"&I9,Skills!$A:$A,Skills!$L:$L,0),_xlfn.XLOOKUP("弱点特效|"&I9,Skills!$A:$A,Skills!$K:$K,0))*Input!$B$9,0)+_xlfn.XLOOKUP("挑战者|"&K9,Skills!$A:$A,Skills!$I:$I,0)*Input!$B$10+_xlfn.XLOOKUP("力量解放|"&P9,Skills!$A:$A,Skills!$I:$I,0)*Input!$B$13+_xlfn.XLOOKUP("精神抖擞|"&Q9,Skills!$A:$A,Skills!$I:$I,0)*Input!$B$14 -> -0.0375 | U9: =MAX(-100%,MIN(100%,T9)) -> -0.0375 | V9: =_xlfn.XLOOKUP("超会心|"&J9,Skills!$A:$A,Skills!$J:$J,1.25) -> 1.3 | W9: =IF(U9>=0,1+U9*(V9-1),1+U9*0.25) -> 0.990625 | X9: =Calc_Current!$B$11-Calc_Current!$B$12*ROUNDDOWN(Calc_Current!$B$13*_xlfn.XLOOKUP("集中|"&N9,Skills!$A:$A,Skills!$M:$M,0),0)-Calc_Current!$B$14*_xlfn.XLOOKUP("纳刀术|"&R9,Skills!$A:$A,Skills!$N:$N,0) -> 298 | Y9: =IF(Calc_Current!$B$4=0,0,(Calc_Current!$B$4+_xlfn.XLOOKUP("属性强化|"&O9,Skills!$A:$A,Skills!$O:$O,0))*_xlfn.XLOOKUP("属性强化|"&O9,Skills!$A:$A,Skills!$P:$P,1)) -> 180 | Z9: =Calc_Current!$B$9/100*S9*Calc_Current!$B$5*Calc_Current!$B$20/100*W9*Input!$B$6 -> 1518.4196 | AA9: =Calc_Current!$B$10*Y9/10*Calc_Current!$B$6*Calc_Current!$B$18/100 -> 25.65 | AB9: =Z9+AA9 -> 1544.0696 | AC9: =IF(F9,AB9*30/X9,NA()) -> 155.44325 | AD9: =IF(F9,AC9/Calc_Current!$B$48-1,NA()) -> 0.012564592 | AE9: =A9&" "&B9&"→"&C9 -> 看破 2→3 | AG9: 集中
A10: {=INDEX($AG$2:$AG$11,ROUNDUP(ROW(A9)/7,0))} -> 看破 | B10: {=_xlfn.SWITCH(A10,"攻击",Input!$F$20,"看破",Input!$F$21,"弱点特效",Input!$F$22,"超会心",Input!$F$23,"挑战者",Input!$F$24,"无伤",Input!$F$25,"怨恨",Input!$F$26,"集中",Input!$F$27,"属性强化",Input!$F$28,"力量解放",Input!$F$29,"精神抖擞",Input!$F$30,"纳刀术",Input!$F$31)} -> 2 | C10: =B10+D10 -> 4 | D10: =MOD(ROW(A9)-1,7)+1 -> 2 | E10: =_xlfn.XLOOKUP(A10&"|0",Skills!$A:$A,Skills!$D:$D) -> 7 | F10: =AND(C10<=E10,_xlfn.XLOOKUP(A10&"|0",Skills!$A:$A,Skills!$F:$F)=TRUE) -> TRUE | G10: =IF($A10="攻击",$C10,Input!$F$20) -> 2 | H10: =IF($A10="看破",$C10,Input!$F$21) -> 4 | I10: =IF($A10="弱点特效",$C10,Input!$F$22) -> 1 | J10: =IF($A10="超会心",$C10,Input!$F$23) -> 1 | K10: =IF($A10="挑战者",$C10,Input!$F$24) -> 3 | L10: =IF($A10="无伤",$C10,Input!$F$25) -> 1 | M10: =IF($A10="怨恨",$C10,Input!$F$26) -> 0 | N10: =IF($A10="集中",$C10,Input!$F$27) -> 0 | O10: =IF($A10="属性强化",$C10,Input!$F$28) -> 0 | P10: =Input!$F$29 -> 0 | Q10: =Input!$F$30 -> 0 | R10: =IF($A10="纳刀术",$C10,Input!$F$31) -> 0 | S10: =(Calc_Current!$B$2+Calc_Current!$B$24+_xlfn.XLOOKUP("攻击|"&G10,Skills!$A:$A,Skills!$G:$G,0)+_xlfn.XLOOKUP("挑战者|"&K10,Skills!$A:$A,Skills!$G:$G,0)*Input!$B$10+_xlfn.XLOOKUP("无伤|"&L10,Skills!$A:$A,Skills!$G:$G,0)*Input!$B$11+_xlfn.XLOOKUP("怨恨|"&M10,Skills!$A:$A,Skills!$G:$G,0)*Input!$B$12)*Calc_Current!$B$26 -> 423.5 | T10: =Calc_Current!$B$3+_xlfn.XLOOKUP("攻击|"&G10,Skills!$A:$A,Skills!$I:$I,0)+_xlfn.XLOOKUP("看破|"&H10,Skills!$A:$A,Skills!$I:$I,0)+IF(Calc_Current!$B$21,IF(Input!$B$5,_xlfn.XLOOKUP("弱点特效|"&I10,Skills!$A:$A,Skills!$L:$L,0),_xlfn.XLOOKUP("弱点特效|"&I10,Skills!$A:$A,Skills!$K:$K,0))*Input!$B$9,0)+_xlfn.XLOOKUP("挑战者|"&K10,Skills!$A:$A,Skills!$I:$I,0)*Input!$B$10+_xlfn.XLOOKUP("力量解放|"&P10,Skills!$A:$A,Skills!$I:$I,0)*Input!$B$13+_xlfn.XLOOKUP("精神抖擞|"&Q10,Skills!$A:$A,Skills!$I:$I,0)*Input!$B$14 -> 0.0125 | U10: =MAX(-100%,MIN(100%,T10)) -> 0.0125 | V10: =_xlfn.XLOOKUP("超会心|"&J10,Skills!$A:$A,Skills!$J:$J,1.25) -> 1.3 | W10: =IF(U10>=0,1+U10*(V10-1),1+U10*0.25) -> 1.00375 | X10: =Calc_Current!$B$11-Calc_Current!$B$12*ROUNDDOWN(Calc_Current!$B$13*_xlfn.XLOOKUP("集中|"&N10,Skills!$A:$A,Skills!$M:$M,0),0)-Calc_Current!$B$14*_xlfn.XLOOKUP("纳刀术|"&R10,Skills!$A:$A,Skills!$N:$N,0) -> 298 | Y10: =IF(Calc_Current!$B$4=0,0,(Calc_Current!$B$4+_xlfn.XLOOKUP("属性强化|"&O10,Skills!$A:$A,Skills!$O:$O,0))*_xlfn.XLOOKUP("属性强化|"&O10,Skills!$A:$A,Skills!$P:$P,1)) -> 180 | Z10: =Calc_Current!$B$9/100*S10*Calc_Current!$B$5*Calc_Current!$B$20/100*W10*Input!$B$6 -> 1538.5374 | AA10: =Calc_Current!$B$10*Y10/10*Calc_Current!$B$6*Calc_Current!$B$18/100 -> 25.65 | AB10: =Z10+AA10 -> 1564.1874 | AC10: =IF(F10,AB10*30/X10,NA()) -> 157.46853 | AD10: =IF(F10,AC10/Calc_Current!$B$48-1,NA()) -> 0.025757414 | AE10: =A10&" "&B10&"→"&C10 -> 看破 2→4 | AG10: 纳刀术
A11: {=INDEX($AG$2:$AG$11,ROUNDUP(ROW(A10)/7,0))} -> 看破 | B11: {=_xlfn.SWITCH(A11,"攻击",Input!$F$20,"看破",Input!$F$21,"弱点特效",Input!$F$22,"超会心",Input!$F$23,"挑战者",Input!$F$24,"无伤",Input!$F$25,"怨恨",Input!$F$26,"集中",Input!$F$27,"属性强化",Input!$F$28,"力量解放",Input!$F$29,"精神抖擞",Input!$F$30,"纳刀术",Input!$F$31)} -> 2 | C11: =B11+D11 -> 5 | D11: =MOD(ROW(A10)-1,7)+1 -> 3 | E11: =_xlfn.XLOOKUP(A11&"|0",Skills!$A:$A,Skills!$D:$D) -> 7 | F11: =AND(C11<=E11,_xlfn.XLOOKUP(A11&"|0",Skills!$A:$A,Skills!$F:$F)=TRUE) -> TRUE | G11: =IF($A11="攻击",$C11,Input!$F$20) -> 2 | H11: =IF($A11="看破",$C11,Input!$F$21) -> 5 | I11: =IF($A11="弱点特效",$C11,Input!$F$22) -> 1 | J11: =IF($A11="超会心",$C11,Input!$F$23) -> 1 | K11: =IF($A11="挑战者",$C11,Input!$F$24) -> 3 | L11: =IF($A11="无伤",$C11,Input!$F$25) -> 1 | M11: =IF($A11="怨恨",$C11,Input!$F$26) -> 0 | N11: =IF($A11="集中",$C11,Input!$F$27) -> 0 | O11: =IF($A11="属性强化",$C11,Input!$F$28) -> 0 | P11: =Input!$F$29 -> 0 | Q11: =Input!$F$30 -> 0 | R11: =IF($A11="纳刀术",$C11,Input!$F$31) -> 0 | S11: =(Calc_Current!$B$2+Calc_Current!$B$24+_xlfn.XLOOKUP("攻击|"&G11,Skills!$A:$A,Skills!$G:$G,0)+_xlfn.XLOOKUP("挑战者|"&K11,Skills!$A:$A,Skills!$G:$G,0)*Input!$B$10+_xlfn.XLOOKUP("无伤|"&L11,Skills!$A:$A,Skills!$G:$G,0)*Input!$B$11+_xlfn.XLOOKUP("怨恨|"&M11,Skills!$A:$A,Skills!$G:$G,0)*Input!$B$12)*Calc_Current!$B$26 -> 423.5 | T11: =Calc_Current!$B$3+_xlfn.XLOOKUP("攻击|"&G11,Skills!$A:$A,Skills!$I:$I,0)+_xlfn.XLOOKUP("看破|"&H11,Skills!$A:$A,Skills!$I:$I,0)+IF(Calc_Current!$B$21,IF(Input!$B$5,_xlfn.XLOOKUP("弱点特效|"&I11,Skills!$A:$A,Skills!$L:$L,0),_xlfn.XLOOKUP("弱点特效|"&I11,Skills!$A:$A,Skills!$K:$K,0))*Input!$B$9,0)+_xlfn.XLOOKUP("挑战者|"&K11,Skills!$A:$A,Skills!$I:$I,0)*Input!$B$10+_xlfn.XLOOKUP("力量解放|"&P11,Skills!$A:$A,Skills!$I:$I,0)*Input!$B$13+_xlfn.XLOOKUP("精神抖擞|"&Q11,Skills!$A:$A,Skills!$I:$I,0)*Input!$B$14 -> 0.0625 | U11: =MAX(-100%,MIN(100%,T11)) -> 0.0625 | V11: =_xlfn.XLOOKUP("超会心|"&J11,Skills!$A:$A,Skills!$J:$J,1.25) -> 1.3 | W11: =IF(U11>=0,1+U11*(V11-1),1+U11*0.25) -> 1.01875 | X11: =Calc_Current!$B$11-Calc_Current!$B$12*ROUNDDOWN(Calc_Current!$B$13*_xlfn.XLOOKUP("集中|"&N11,Skills!$A:$A,Skills!$M:$M,0),0)-Calc_Current!$B$14*_xlfn.XLOOKUP("纳刀术|"&R11,Skills!$A:$A,Skills!$N:$N,0) -> 298 | Y11: =IF(Calc_Current!$B$4=0,0,(Calc_Current!$B$4+_xlfn.XLOOKUP("属性强化|"&O11,Skills!$A:$A,Skills!$O:$O,0))*_xlfn.XLOOKUP("属性强化|"&O11,Skills!$A:$A,Skills!$P:$P,1)) -> 180 | Z11: =Calc_Current!$B$9/100*S11*Calc_Current!$B$5*Calc_Current!$B$20/100*W11*Input!$B$6 -> 1561.5293 | AA11: =Calc_Current!$B$10*Y11/10*Calc_Current!$B$6*Calc_Current!$B$18/100 -> 25.65 | AB11: =Z11+AA11 -> 1587.1793 | AC11: =IF(F11,AB11*30/X11,NA()) -> 159.78315 | AD11: =IF(F11,AC11/Calc_Current!$B$48-1,NA()) -> 0.040834924 | AE11: =A11&" "&B11&"→"&C11 -> 看破 2→5 | AG11: 属性强化
A12: {=INDEX($AG$2:$AG$11,ROUNDUP(ROW(A11)/7,0))} -> 看破 | B12: {=_xlfn.SWITCH(A12,"攻击",Input!$F$20,"看破",Input!$F$21,"弱点特效",Input!$F$22,"超会心",Input!$F$23,"挑战者",Input!$F$24,"无伤",Input!$F$25,"怨恨",Input!$F$26,"集中",Input!$F$27,"属性强化",Input!$F$28,"力量解放",Input!$F$29,"精神抖擞",Input!$F$30,"纳刀术",Input!$F$31)} -> 2 | C12: =B12+D12 -> 6 | D12: =MOD(ROW(A11)-1,7)+1 -> 4 | E12: =_xlfn.XLOOKUP(A12&"|0",Skills!$A:$A,Skills!$D:$D) -> 7 | F12: =AND(C12<=E12,_xlfn.XLOOKUP(A12&"|0",Skills!$A:$A,Skills!$F:$F)=TRUE) -> TRUE | G12: =IF($A12="攻击",$C12,Input!$F$20) -> 2 | H12: =IF($A12="看破",$C12,Input!$F$21) -> 6 | I12: =IF($A12="弱点特效",$C12,Input!$F$22) -> 1 | J12: =IF($A12="超会心",$C12,Input!$F$23) -> 1 | K12: =IF($A12="挑战者",$C12,Input!$F$24) -> 3 | L12: =IF($A12="无伤",$C12,Input!$F$25) -> 1 | M12: =IF($A12="怨恨",$C12,Input!$F$26) -> 0 | N12: =IF($A12="集中",$C12,Input!$F$27) -> 0 | O12: =IF($A12="属性强化",$C12,Input!$F$28) -> 0 | P12: =Input!$F$29 -> 0 | Q12: =Input!$F$30 -> 0 | R12: =IF($A12="纳刀术",$C12,Input!$F$31) -> 0 | S12: =(Calc_Current!$B$2+Calc_Current!$B$24+_xlfn.XLOOKUP("攻击|"&G12,Skills!$A:$A,Skills!$G:$G,0)+_xlfn.XLOOKUP("挑战者|"&K12,Skills!$A:$A,Skills!$G:$G,0)*Input!$B$10+_xlfn.XLOOKUP("无伤|"&L12,Skills!$A:$A,Skills!$G:$G,0)*Input!$B$11+_xlfn.XLOOKUP("怨恨|"&M12,Skills!$A:$A,Skills!$G:$G,0)*Input!$B$12)*Calc_Current!$B$26 -> 423.5 | T12: =Calc_Current!$B$3+_xlfn.XLOOKUP("攻击|"&G12,Skills!$A:$A,Skills!$I:$I,0)+_xlfn.XLOOKUP("看破|"&H12,Skills!$A:$A,Skills!$I:$I,0)+IF(Calc_Current!$B$21,IF(Input!$B$5,_xlfn.XLOOKUP("弱点特效|"&I12,Skills!$A:$A,Skills!$L:$L,0),_xlfn.XLOOKUP("弱点特效|"&I12,Skills!$A:$A,Skills!$K:$K,0))*Input!$B$9,0)+_xlfn.XLOOKUP("挑战者|"&K12,Skills!$A:$A,Skills!$I:$I,0)*Input!$B$10+_xlfn.XLOOKUP("力量解放|"&P12,Skills!$A:$A,Skills!$I:$I,0)*Input!$B$13+_xlfn.XLOOKUP("精神抖擞|"&Q12,Skills!$A:$A,Skills!$I:$I,0)*Input!$B$14 -> 0.1125 | U12: =MAX(-100%,MIN(100%,T12)) -> 0.1125 | V12: =_xlfn.XLOOKUP("超会心|"&J12,Skills!$A:$A,Skills!$J:$J,1.25) -> 1.3 | W12: =IF(U12>=0,1+U12*(V12-1),1+U12*0.25) -> 1.03375 | X12: =Calc_Current!$B$11-Calc_Current!$B$12*ROUNDDOWN(Calc_Current!$B$13*_xlfn.XLOOKUP("集中|"&N12,Skills!$A:$A,Skills!$M:$M,0),0)-Calc_Current!$B$14*_xlfn.XLOOKUP("纳刀术|"&R12,Skills!$A:$A,Skills!$N:$N,0) -> 298 | Y12: =IF(Calc_Current!$B$4=0,0,(Calc_Current!$B$4+_xlfn.XLOOKUP("属性强化|"&O12,Skills!$A:$A,Skills!$O:$O,0))*_xlfn.XLOOKUP("属性强化|"&O12,Skills!$A:$A,Skills!$P:$P,1)) -> 180 | Z12: =Calc_Current!$B$9/100*S12*Calc_Current!$B$5*Calc_Current!$B$20/100*W12*Input!$B$6 -> 1584.5211 | AA12: =Calc_Current!$B$10*Y12/10*Calc_Current!$B$6*Calc_Current!$B$18/100 -> 25.65 | AB12: =Z12+AA12 -> 1610.1711 | AC12: =IF(F12,AB12*30/X12,NA()) -> 162.09776 | AD12: =IF(F12,AC12/Calc_Current!$B$48-1,NA()) -> 0.055912435 | AE12: =A12&" "&B12&"→"&C12 -> 看破 2→6
A13: {=INDEX($AG$2:$AG$11,ROUNDUP(ROW(A12)/7,0))} -> 看破 | B13: {=_xlfn.SWITCH(A13,"攻击",Input!$F$20,"看破",Input!$F$21,"弱点特效",Input!$F$22,"超会心",Input!$F$23,"挑战者",Input!$F$24,"无伤",Input!$F$25,"怨恨",Input!$F$26,"集中",Input!$F$27,"属性强化",Input!$F$28,"力量解放",Input!$F$29,"精神抖擞",Input!$F$30,"纳刀术",Input!$F$31)} -> 2 | C13: =B13+D13 -> 7 | D13: =MOD(ROW(A12)-1,7)+1 -> 5 | E13: =_xlfn.XLOOKUP(A13&"|0",Skills!$A:$A,Skills!$D:$D) -> 7 | F13: =AND(C13<=E13,_xlfn.XLOOKUP(A13&"|0",Skills!$A:$A,Skills!$F:$F)=TRUE) -> TRUE | G13: =IF($A13="攻击",$C13,Input!$F$20) -> 2 | H13: =IF($A13="看破",$C13,Input!$F$21) -> 7 | I13: =IF($A13="弱点特效",$C13,Input!$F$22) -> 1 | J13: =IF($A13="超会心",$C13,Input!$F$23) -> 1 | K13: =IF($A13="挑战者",$C13,Input!$F$24) -> 3 | L13: =IF($A13="无伤",$C13,Input!$F$25) -> 1 | M13: =IF($A13="怨恨",$C13,Input!$F$26) -> 0 | N13: =IF($A13="集中",$C13,Input!$F$27) -> 0 | O13: =IF($A13="属性强化",$C13,Input!$F$28) -> 0 | P13: =Input!$F$29 -> 0 | Q13: =Input!$F$30 -> 0 | R13: =IF($A13="纳刀术",$C13,Input!$F$31) -> 0 | S13: =(Calc_Current!$B$2+Calc_Current!$B$24+_xlfn.XLOOKUP("攻击|"&G13,Skills!$A:$A,Skills!$G:$G,0)+_xlfn.XLOOKUP("挑战者|"&K13,Skills!$A:$A,Skills!$G:$G,0)*Input!$B$10+_xlfn.XLOOKUP("无伤|"&L13,Skills!$A:$A,Skills!$G:$G,0)*Input!$B$11+_xlfn.XLOOKUP("怨恨|"&M13,Skills!$A:$A,Skills!$G:$G,0)*Input!$B$12)*Calc_Current!$B$26 -> 423.5 | T13: =Calc_Current!$B$3+_xlfn.XLOOKUP("攻击|"&G13,Skills!$A:$A,Skills!$I:$I,0)+_xlfn.XLOOKUP("看破|"&H13,Skills!$A:$A,Skills!$I:$I,0)+IF(Calc_Current!$B$21,IF(Input!$B$5,_xlfn.XLOOKUP("弱点特效|"&I13,Skills!$A:$A,Skills!$L:$L,0),_xlfn.XLOOKUP("弱点特效|"&I13,Skills!$A:$A,Skills!$K:$K,0))*Input!$B$9,0)+_xlfn.XLOOKUP("挑战者|"&K13,Skills!$A:$A,Skills!$I:$I,0)*Input!$B$10+_xlfn.XLOOKUP("力量解放|"&P13,Skills!$A:$A,Skills!$I:$I,0)*Input!$B$13+_xlfn.XLOOKUP("精神抖擞|"&Q13,Skills!$A:$A,Skills!$I:$I,0)*Input!$B$14 -> 0.2125 | U13: =MAX(-100%,MIN(100%,T13)) -> 0.2125 | V13: =_xlfn.XLOOKUP("超会心|"&J13,Skills!$A:$A,Skills!$J:$J,1.25) -> 1.3 | W13: =IF(U13>=0,1+U13*(V13-1),1+U13*0.25) -> 1.06375 | X13: =Calc_Current!$B$11-Calc_Current!$B$12*ROUNDDOWN(Calc_Current!$B$13*_xlfn.XLOOKUP("集中|"&N13,Skills!$A:$A,Skills!$M:$M,0),0)-Calc_Current!$B$14*_xlfn.XLOOKUP("纳刀术|"&R13,Skills!$A:$A,Skills!$N:$N,0) -> 298 | Y13: =IF(Calc_Current!$B$4=0,0,(Calc_Current!$B$4+_xlfn.XLOOKUP("属性强化|"&O13,Skills!$A:$A,Skills!$O:$O,0))*_xlfn.XLOOKUP("属性强化|"&O13,Skills!$A:$A,Skills!$P:$P,1)) -> 180 | Z13: =Calc_Current!$B$9/100*S13*Calc_Current!$B$5*Calc_Current!$B$20/100*W13*Input!$B$6 -> 1630.5048 | AA13: =Calc_Current!$B$10*Y13/10*Calc_Current!$B$6*Calc_Current!$B$18/100 -> 25.65 | AB13: =Z13+AA13 -> 1656.1548 | AC13: =IF(F13,AB13*30/X13,NA()) -> 166.72699 | AD13: =IF(F13,AC13/Calc_Current!$B$48-1,NA()) -> 0.086067456 | AE13: =A13&" "&B13&"→"&C13 -> 看破 2→7
